<?xml version="1.0" ?>
<!-- =================================================================================== -->
<!-- |    This document was autogenerated by xacro from tiago_pro.urdf.xacro           | -->
<!-- |    EDITING THIS FILE BY HAND IS NOT RECOMMENDED                                 | -->
<!-- =================================================================================== -->
<!--

  Copyright (c) 2022 PAL Robotics S.L. All rights reserved.
  Licensed under the Apache License, Version 2.0 (the "License");
  you may not use this file except in compliance with the License.
  You may obtain a copy of the License at
      http://www.apache.org/licenses/LICENSE-2.0
  Unless required by applicable law or agreed to in writing, software
  distributed under the License is distributed on an "AS IS" BASIS,
  WITHOUT WARRANTIES OR CONDITIONS OF ANY KIND, either express or implied.
  See the License for the specific language governing permissions and
  limitations under the License.
-->
<robot name="tiago_pro">
  <material name="Blue">
    <color rgba="0.0 0.0 0.8 1.0"/>
  </material>
  <material name="Green">
    <color rgba="0.0 0.8 0.0 1.0"/>
  </material>
  <material name="Grey">
    <color rgba="0.7 0.7 0.7 1.0"/>
  </material>
  <material name="LightGrey">
    <color rgba="0.9 0.9 0.9 1.0"/>
  </material>
  <material name="DarkGrey">
    <color rgba="0.1 0.1 0.1 1.0"/>
  </material>
  <material name="Red">
    <color rgba="0.8 0.0 0.0 1.0"/>
  </material>
  <material name="White">
    <color rgba="1.0 1.0 1.0 1.0"/>
  </material>
  <material name="Yellow">
    <color rgba="0.96 0.88 0.14 1.0"/>
  </material>
  <material name="Black">
    <color rgba="0.0 0.0 0.0 1.0"/>
  </material>
  <material name="FlatBlack">
    <color rgba="0.09 0.09 0.09 1.0"/>
  </material>
  <material name="Orange">
    <color rgba="1.0 0.487 0.0 1.0"/>
  </material>
  <material name="pal/Orange">
    <color rgba="0.91373 0.61568 0.29411 1.0"/>
  </material>
  <material name="pal/DarkGrey">
    <color rgba="0.29804 0.29804 0.29804 1"/>
  </material>
  <gazebo>
    <plugin filename="libgazebo_ros_control.so" name="gazebo_ros_control">
      <ns/>
      <robotSimType>pal_hardware_gazebo/PalHardwareGazebo</robotSimType>
      <robotNamespace/>
      <controlPeriod>0.001</controlPeriod>
    </plugin>
    <plugin filename="libgazebo_ros_force_based_move.so" name="gazebo_force_based_move">
      <commandTopic>mobile_base_controller/cmd_vel</commandTopic>
      <odometryTopic>mobile_base_controller/odom</odometryTopic>
      <odometryFrame>odom</odometryFrame>
      <odometryRate>50.0</odometryRate>
      <robotBaseFrame>base_footprint</robotBaseFrame>
      <publishOdometryTf>true</publishOdometryTf>
    </plugin>
    <plugin filename="libgazebo_ros_p3d.so" name="gazebo_ros_p3d">
      <bodyName>base_footprint</bodyName>
      <topicName>ground_truth_odom</topicName>
      <alwaysOn>true</alwaysOn>
      <updateRate>100.0</updateRate>
    </plugin>
  </gazebo>
  <gazebo>
    <plugin filename="libgazebo_world_odometry.so" name="gazebo_ros_odometry">
      <frameName>base_footprint</frameName>
      <topicName>floating_base_pose_simulated</topicName>
    </plugin>
  </gazebo>
  <gazebo reference="base_imu_link">
    <!-- this is expected to be reparented to pelvis with appropriate offset
         when imu_link is reduced by fixed joint reduction -->
    <!-- todo: this is working with gazebo 1.4, need to write a unit test -->
    <sensor name="imu_sensor" type="imu">
      <always_on>1</always_on>
      <update_rate>1000.0</update_rate>
      <imu>
        <noise>
          <type>gaussian</type>
          <!-- Noise parameters from Boston Dynamics
               (http://gazebosim.org/wiki/Sensor_noise):
                 rates (rad/s): mean=0, stddev=2e-4
                 accels (m/s/s): mean=0, stddev=1.7e-2
                 rate bias (rad/s): 5e-6 - 1e-5
                 accel bias (m/s/s): 1e-1
               Experimentally, simulation provide rates with noise of
               about 1e-3 rad/s and accels with noise of about 1e-1 m/s/s.
               So we don't expect to see the noise unless number of inner iterations
               are increased.

               We will add bias.  In this model, bias is sampled once for rates
               and once for accels at startup; the sign (negative or positive)
               of each bias is then switched with equal probability.  Thereafter,
               the biases are fixed additive offsets.  We choose
               bias means and stddevs to produce biases close to the provided
               data. -->
          <rate>
            <mean>0.0</mean>
            <stddev>2e-4</stddev>
            <bias_mean>0.0000075</bias_mean>
            <bias_stddev>0.0000008</bias_stddev>
          </rate>
          <accel>
            <mean>0.0</mean>
            <stddev>1.7e-2</stddev>
            <bias_mean>0.1</bias_mean>
            <bias_stddev>0.001</bias_stddev>
          </accel>
        </noise>
      </imu>
    </sensor>
  </gazebo>
  <link name="base_rear_laser_link" type="laser">
    <inertial>
      <origin rpy="0 0 0" xyz="-0.02559000000 -0.00056000000 -0.05732000000"/>
      <mass value="0.28922000000"/>
      <inertia ixx="0.00002628919" ixy="0.00000024298" ixz="-0.00000368129" iyy="0.00003374542" iyz="-0.00000001330" izz="0.00005832599"/>
    </inertial>
    <visual>
      <origin rpy="0 0 0" xyz="0 0 0"/>
      <geometry>
        <mesh filename="package://example-robot-data/robots/tiago2_description/meshes/sensors/sick_tim551.stl"/>
      </geometry>
      <material name="DarkGrey"/>
    </visual>
    <collision>
      <origin rpy="0 0 0" xyz="0 0 0"/>
      <geometry>
        <cylinder length="0.04" radius="0.02"/>
      </geometry>
    </collision>
  </link>
  <joint name="base_rear_laser_joint" type="fixed">
    <axis xyz="0 1 0"/>
    <origin rpy="-3.141592653589793 0 2.356194490192345" xyz="-0.27512 0.18297 0.13244"/>
    <parent link="base_link"/>
    <child link="base_rear_laser_link"/>
  </joint>
  <gazebo reference="base_rear_laser_link">
    <!-- Using gpu laser instead of normal laser because it was causing issues with the omni_base -->
    <sensor name="base_rear_laser" type="gpu_ray">
      <pose>0 0 0 0 0 0</pose>
      <update_rate>10</update_rate>
      <visualize>true</visualize>
      <ray>
        <scan>
          <horizontal>
            <!-- 818 (270/0.33) steps in 270deg fov -->
            <samples>818.0</samples>
            <resolution>1</resolution>
            <!-- not the sensor resolution; just 1 -->
            <min_angle>-2.356194490192345</min_angle>
            <max_angle>2.356194490192345</max_angle>
          </horizontal>
        </scan>
        <range>
          <min>0.05</min>
          <max>25.0</max>
          <resolution>0.001</resolution>
        </range>
      </ray>
      <plugin filename="libgazebo_ros_gpu_laser.so" name="gazebo_ros_sick_laser">
        <gaussianNoise>0.06</gaussianNoise>
        <alwaysOn>true</alwaysOn>
        <updateRate>10</updateRate>
        <topicName>scan_rear_raw</topicName>
        <frameName>base_rear_laser_link</frameName>
      </plugin>
    </sensor>
    <material>Gazebo/DarkGrey</material>
  </gazebo>
  <link name="base_front_laser_link" type="laser">
    <inertial>
      <origin rpy="0 0 0" xyz="-0.02559000000 -0.00056000000 -0.05732000000"/>
      <mass value="0.28922000000"/>
      <inertia ixx="0.00002628919" ixy="0.00000024298" ixz="-0.00000368129" iyy="0.00003374542" iyz="-0.00000001330" izz="0.00005832599"/>
    </inertial>
    <visual>
      <origin rpy="0 0 0" xyz="0 0 0"/>
      <geometry>
        <mesh filename="package://example-robot-data/robots/tiago2_description/meshes/sensors/sick_tim551.stl"/>
      </geometry>
      <material name="DarkGrey"/>
    </visual>
    <collision>
      <origin rpy="0 0 0" xyz="0 0 0"/>
      <geometry>
        <cylinder length="0.04" radius="0.02"/>
      </geometry>
    </collision>
  </link>
  <joint name="base_front_laser_joint" type="fixed">
    <axis xyz="0 1 0"/>
    <origin rpy="-3.141592653589793 0 -0.7853981633974483" xyz="0.27512 -0.18297 0.13244"/>
    <parent link="base_link"/>
    <child link="base_front_laser_link"/>
  </joint>
  <gazebo reference="base_front_laser_link">
    <!-- Using gpu laser instead of normal laser because it was causing issues with the omni_base -->
    <sensor name="base_front_laser" type="gpu_ray">
      <pose>0 0 0 0 0 0</pose>
      <update_rate>10</update_rate>
      <visualize>true</visualize>
      <ray>
        <scan>
          <horizontal>
            <!-- 818 (270/0.33) steps in 270deg fov -->
            <samples>818.0</samples>
            <resolution>1</resolution>
            <!-- not the sensor resolution; just 1 -->
            <min_angle>-2.356194490192345</min_angle>
            <max_angle>2.356194490192345</max_angle>
          </horizontal>
        </scan>
        <range>
          <min>0.05</min>
          <max>25.0</max>
          <resolution>0.001</resolution>
        </range>
      </ray>
      <plugin filename="libgazebo_ros_gpu_laser.so" name="gazebo_ros_sick_laser">
        <gaussianNoise>0.06</gaussianNoise>
        <alwaysOn>true</alwaysOn>
        <updateRate>10</updateRate>
        <topicName>scan_front_raw</topicName>
        <frameName>base_front_laser_link</frameName>
      </plugin>
    </sensor>
    <material>Gazebo/DarkGrey</material>
  </gazebo>
  <!-- Virtual Base Laser Link -->
  <joint name="virtual_base_laser_joint" type="fixed">
    <parent link="base_link"/>
    <child link="virtual_base_laser_link"/>
    <origin rpy="0 0 0" xyz="0 0 0.13244"/>
  </joint>
  <link name="virtual_base_laser_link">
    <inertial>
      <origin rpy="0 0 0" xyz="0 0 0"/>
      <mass value="0.0001"/>
      <inertia ixx="0.0001" ixy="0" ixz="0" iyy="0.0001" iyz="0" izz="0.0001"/>
    </inertial>
  </link>
  <!-- Base footprint -->
  <link name="base_link">
    <inertial>
      <origin rpy="0 0 0" xyz="0.0026742 0.00027459 0.086363"/>
      <mass value="34.047"/>
      <inertia ixx="0.22777" ixy="0.00035979" ixz="0.00015269" iyy="0.29991" iyz="1.7872E-05" izz="0.46036"/>
    </inertial>
    <visual>
      <origin rpy="0 0 0" xyz="0 0 0"/>
      <geometry>
        <mesh filename="package://example-robot-data/robots/tiago2_description/meshes/omni_base/base/base_link.stl"/>
      </geometry>
      <material name="">
        <color rgba="0.75294 0.75294 0.75294 1"/>
      </material>
    </visual>
    <collision>
      <origin rpy="0 0 0" xyz="0 0 0.18925"/>
      <geometry>
        <box size="0.717 0.497 0.0845"/>
      </geometry>
    </collision>
    <collision>
      <origin rpy="0 0 0" xyz="0 0 0.132"/>
      <geometry>
        <box size="0.58 0.39 0.03"/>
      </geometry>
    </collision>
    <collision>
      <origin rpy="0 0 0" xyz="0 0 0.0335"/>
      <geometry>
        <box size="0.705 0.48 0.167"/>
      </geometry>
    </collision>
  </link>
  <link name="base_footprint"/>
  <joint name="base_footprint_joint" type="fixed">
    <origin rpy="0 0 0" xyz="0 0 0.0762"/>
    <child link="base_link"/>
    <parent link="base_footprint"/>
  </joint>
  <!-- gazebo parameters are given here for base_link through base_footprint -->
  <gazebo reference="base_footprint">
    <kp>100000000.0</kp>
    <kd>10.0</kd>
    <mu1>0.1</mu1>
    <mu2>0.1</mu2>
    <fdir1>1 0 0</fdir1>
    <maxVel>10.0</maxVel>
    <minDepth>0.0005</minDepth>
    <laserRetro>0</laserRetro>
  </gazebo>
  <link name="base_imu_link">
    <inertial>
      <mass value="0.01"/>
      <origin xyz="0 0 0"/>
      <inertia ixx="0.000001" ixy="0" ixz="0" iyy="0.000001" iyz="0" izz="0.000001"/>
    </inertial>
    <!--visual>
        <origin rpy="0 0 0" xyz="0 0 0"/>
        <geometry>
          <box size="0.01 0.01 0.01"/>
        </geometry>
      </visual-->
  </link>
  <joint name="base_imu_joint" type="fixed">
    <parent link="base_link"/>
    <child link="base_imu_link"/>
    <origin rpy="0 0 1.5707963267948966" xyz="-0.287 0 0.092163"/>
  </joint>
  <gazebo reference="base_imu_link">
    <sensor name="base_imu_sensor" type="imu">
      <always_on>1</always_on>
      <update_rate>100.0</update_rate>
      <imu>
        <noise>
          <type>gaussian</type>
          <rate>
            <mean>0.0</mean>
            <stddev>2e-4</stddev>
            <bias_mean>0.0000075</bias_mean>
            <bias_stddev>0.0000008</bias_stddev>
          </rate>
          <accel>
            <mean>0.0</mean>
            <stddev>1.7e-2</stddev>
            <bias_mean>0.1</bias_mean>
            <bias_stddev>0.001</bias_stddev>
          </accel>
        </noise>
      </imu>
    </sensor>
  </gazebo>
  <!-- Docking link -->
  <link name="base_dock_link">
    <inertial>
      <origin rpy="0 0 0" xyz="-0.0037082 1.5226E-18 -4.1633E-17"/>
      <mass value="0.032242"/>
      <inertia ixx="2.1302E-05" ixy="-1.0461E-21" ixz="6.6555E-22" iyy="1.2058E-05" iyz="-1.9453E-21" izz="1.0058E-05"/>
    </inertial>
    <visual>
      <origin rpy="0 0 0" xyz="0 0 0"/>
      <geometry>
        <mesh filename="package://example-robot-data/robots/tiago2_description/meshes/omni_base/base/base_dock_link.stl"/>
      </geometry>
      <material name="">
        <color rgba="0.25098 0.25098 0.25098 1"/>
      </material>
    </visual>
    <collision>
      <origin rpy="0 0 0" xyz="0 0 0"/>
      <geometry>
        <mesh filename="package://example-robot-data/robots/tiago2_description/meshes/omni_base/base/base_dock_link.stl"/>
      </geometry>
    </collision>
  </link>
  <joint name="base_dock" type="fixed">
    <origin rpy="0 0 0" xyz="0.3535 0 0.0596"/>
    <parent link="base_link"/>
    <child link="base_dock_link"/>
    <axis xyz="0 0 0"/>
  </joint>
  <link name="base_antenna_right_link">
    <inertial>
      <origin rpy="0 0 0" xyz="0.027807 -0.0085125 0.015138"/>
      <mass value="0.02311"/>
      <inertia ixx="2.3107E-06" ixy="5.0914e-06" ixz="8.5605E-08" iyy="1.7384E-05" iyz="-2.6206e-08" izz="1.8542E-05"/>
    </inertial>
    <visual>
      <origin rpy="0 0 0" xyz="0 0 0"/>
      <geometry>
        <mesh filename="package://example-robot-data/robots/tiago2_description/meshes/omni_base/base/base_antena_link.stl" scale="1 1 1"/>
      </geometry>
      <material name="">
        <color rgba="0.75294 0.75294 0.75294 1"/>
      </material>
    </visual>
    <collision>
      <origin rpy="0 0 0" xyz="0 0 0"/>
      <geometry>
        <mesh filename="package://example-robot-data/robots/tiago2_description/meshes/omni_base/base/base_antena_link.stl" scale="1 1 1"/>
      </geometry>
    </collision>
  </link>
  <joint name="base_antenna_right_joint" type="fixed">
    <origin rpy="0 0 0" xyz="-0.2015 -0.13 0.2165"/>
    <parent link="base_link"/>
    <child link="base_antenna_right_link"/>
    <axis xyz="0 0 0"/>
  </joint>
  <gazebo reference="base_antenna_right_link">
    <material>Gazebo/Black</material>
  </gazebo>
  <link name="base_antenna_left_link">
    <inertial>
      <origin rpy="0 0 0" xyz="0.027807 0.0085125 0.015138"/>
      <mass value="0.02311"/>
      <inertia ixx="2.3107E-06" ixy="-5.0914e-06" ixz="8.5605E-08" iyy="1.7384E-05" iyz="2.6206e-08" izz="1.8542E-05"/>
    </inertial>
    <visual>
      <origin rpy="0 0 0" xyz="0 0 0"/>
      <geometry>
        <mesh filename="package://example-robot-data/robots/tiago2_description/meshes/omni_base/base/base_antena_link.stl" scale="1 -1 1"/>
      </geometry>
      <material name="">
        <color rgba="0.75294 0.75294 0.75294 1"/>
      </material>
    </visual>
    <collision>
      <origin rpy="0 0 0" xyz="0 0 0"/>
      <geometry>
        <mesh filename="package://example-robot-data/robots/tiago2_description/meshes/omni_base/base/base_antena_link.stl" scale="1 -1 1"/>
      </geometry>
    </collision>
  </link>
  <joint name="base_antenna_left_joint" type="fixed">
    <origin rpy="0 0 0" xyz="-0.2015 0.13 0.2165"/>
    <parent link="base_link"/>
    <child link="base_antenna_left_link"/>
    <axis xyz="0 0 0"/>
  </joint>
  <gazebo reference="base_antenna_left_link">
    <material>Gazebo/Black</material>
  </gazebo>
  <link name="suspension_front_right_link">
    <inertial>
      <origin rpy="0 0 0" xyz="-0.058182 -0.0043908 -0.0057695"/>
      <mass value="1.2879"/>
      <inertia ixx="0.0015947" ixy="-0.00013183" ixz="1.7315E-05" iyy="0.00060158" iyz="-6.0731e-05" izz="0.0015861"/>
    </inertial>
    <visual>
      <origin rpy="0 0 0" xyz="0 0 0"/>
      <geometry>
        <mesh filename="package://example-robot-data/robots/tiago2_description/meshes/omni_base/wheels/suspension_front_link.stl" scale="1 1.0 1"/>
      </geometry>
      <material name="">
        <color rgba="0.79216 0.81961 0.93333 1"/>
      </material>
    </visual>
    <collision>
      <origin rpy="0 0 0" xyz="0 0 0"/>
      <geometry>
        <mesh filename="package://example-robot-data/robots/tiago2_description/meshes/omni_base/wheels/suspension_front_link.stl" scale="1 1.0 1"/>
      </geometry>
    </collision>
    <kinematic>0</kinematic>
    <gravity>1</gravity>
  </link>
  <!-- Changed joint type to fixed joint. It is observed that the robot is loosing contact points due to some issues with the Gazebo Physics Engine. This makes the robot drift in localization when static due to added noise -->
  <joint name="suspension_front_right_joint" type="fixed">
    <origin rpy="0 0 -1.5707963267948966" xyz="0.244 -0.1725 0"/>
    <parent link="base_link"/>
    <child link="suspension_front_right_link"/>
    <axis xyz="0 0 1"/>
  </joint>
  <link name="wheel_front_right_link">
    <inertial>
      <origin rpy="0 0 0" xyz="5.4922e-09 6.9775e-05 0.011144"/>
      <mass value="0.70767"/>
      <inertia ixx="0.00035492" ixy="7.5685e-13" ixz="3.8795E-11" iyy="0.00035529" iyz="-2.0284e-07" izz="0.00040131"/>
    </inertial>
    <visual>
      <origin rpy="0 0 0" xyz="0 0 0"/>
      <geometry>
        <mesh filename="package://example-robot-data/robots/tiago2_description/meshes/omni_base/wheels/wheel_link.stl" scale="1 1 1.0"/>
      </geometry>
      <material name="DarkGrey"/>
    </visual>
    <collision>
      <origin rpy="0 0 0" xyz="0 0 0"/>
      <geometry>
        <cylinder length="0.05" radius="0.0762"/>
      </geometry>
    </collision>
  </link>
  <joint name="wheel_front_right_joint" type="continuous">
    <origin rpy="-1.5707963267948966 0 1.5707963267948966" xyz="0.050675 0 0"/>
    <parent link="suspension_front_right_link"/>
    <child link="wheel_front_right_link"/>
    <axis xyz="0 0 1"/>
    <limit effort="6.0" velocity="13.123359580052492"/>
  </joint>
  <transmission name="wheel_front_right_trans">
    <type>transmission_interface/SimpleTransmission</type>
    <actuator name="wheel_front_right_motor">
      <mechanicalReduction>1.0</mechanicalReduction>
    </actuator>
    <joint name="wheel_front_right_joint">
      <hardwareInterface>hardware_interface/VelocityJointInterface</hardwareInterface>
      <hardwareInterface>hardware_interface/JointStateInterface</hardwareInterface>
    </joint>
  </transmission>
  <!-- Contact model for the wheel surface -->
  <gazebo reference="wheel_front_right_link">
    <kp>1000000.0</kp>
    <kd>1000.0</kd>
    <mu1>0.0</mu1>
    <mu2>0.0</mu2>
    <fdir1>1 0 0</fdir1>
    <maxVel>1.0</maxVel>
    <minDepth>0.00</minDepth>
    <implicitSpringDamper>1</implicitSpringDamper>
    <material>Gazebo/DarkGrey</material>
  </gazebo>
  <link name="suspension_front_left_link">
    <inertial>
      <origin rpy="0 0 0" xyz="-0.058182 0.0043908 -0.0057695"/>
      <mass value="1.2879"/>
      <inertia ixx="0.0015947" ixy="0.00013183" ixz="1.7315E-05" iyy="0.00060158" iyz="6.0731e-05" izz="0.0015861"/>
    </inertial>
    <visual>
      <origin rpy="0 0 0" xyz="0 0 0"/>
      <geometry>
        <mesh filename="package://example-robot-data/robots/tiago2_description/meshes/omni_base/wheels/suspension_front_link.stl" scale="1 -1.0 1"/>
      </geometry>
      <material name="">
        <color rgba="0.79216 0.81961 0.93333 1"/>
      </material>
    </visual>
    <collision>
      <origin rpy="0 0 0" xyz="0 0 0"/>
      <geometry>
        <mesh filename="package://example-robot-data/robots/tiago2_description/meshes/omni_base/wheels/suspension_front_link.stl" scale="1 -1.0 1"/>
      </geometry>
    </collision>
    <kinematic>0</kinematic>
    <gravity>1</gravity>
  </link>
  <!-- Changed joint type to fixed joint. It is observed that the robot is loosing contact points due to some issues with the Gazebo Physics Engine. This makes the robot drift in localization when static due to added noise -->
  <joint name="suspension_front_left_joint" type="fixed">
    <origin rpy="0 0 1.5707963267948966" xyz="0.244 0.1725 0"/>
    <parent link="base_link"/>
    <child link="suspension_front_left_link"/>
    <axis xyz="0 0 1"/>
  </joint>
  <link name="wheel_front_left_link">
    <inertial>
      <origin rpy="0 0 0" xyz="5.4922e-09 -6.9775e-05 -0.011144"/>
      <mass value="0.70767"/>
      <inertia ixx="0.00035492" ixy="7.5685e-13" ixz="3.8795E-11" iyy="0.00035529" iyz="-2.0284e-07" izz="0.00040131"/>
    </inertial>
    <visual>
      <origin rpy="0 0 0" xyz="0 0 0"/>
      <geometry>
        <mesh filename="package://example-robot-data/robots/tiago2_description/meshes/omni_base/wheels/wheel_link.stl" scale="1 1 -1.0"/>
      </geometry>
      <material name="DarkGrey"/>
    </visual>
    <collision>
      <origin rpy="0 0 0" xyz="0 0 0"/>
      <geometry>
        <cylinder length="0.05" radius="0.0762"/>
      </geometry>
    </collision>
  </link>
  <joint name="wheel_front_left_joint" type="continuous">
    <origin rpy="-1.5707963267948966 0 -1.5707963267948966" xyz="0.050675 0 0"/>
    <parent link="suspension_front_left_link"/>
    <child link="wheel_front_left_link"/>
    <axis xyz="0 0 1"/>
    <limit effort="6.0" velocity="13.123359580052492"/>
  </joint>
  <transmission name="wheel_front_left_trans">
    <type>transmission_interface/SimpleTransmission</type>
    <actuator name="wheel_front_left_motor">
      <mechanicalReduction>1.0</mechanicalReduction>
    </actuator>
    <joint name="wheel_front_left_joint">
      <hardwareInterface>hardware_interface/VelocityJointInterface</hardwareInterface>
      <hardwareInterface>hardware_interface/JointStateInterface</hardwareInterface>
    </joint>
  </transmission>
  <!-- Contact model for the wheel surface -->
  <gazebo reference="wheel_front_left_link">
    <kp>1000000.0</kp>
    <kd>1000.0</kd>
    <mu1>0.0</mu1>
    <mu2>0.0</mu2>
    <fdir1>1 0 0</fdir1>
    <maxVel>1.0</maxVel>
    <minDepth>0.00</minDepth>
    <implicitSpringDamper>1</implicitSpringDamper>
    <material>Gazebo/DarkGrey</material>
  </gazebo>
  <link name="suspension_rear_right_link">
    <inertial>
      <origin rpy="0 0 0" xyz="-0.058182 0.0043908 -0.0057695"/>
      <mass value="1.2879"/>
      <inertia ixx="0.0015947" ixy="0.00013183" ixz="1.7315E-05" iyy="0.00060158" iyz="6.0731e-05" izz="0.0015861"/>
    </inertial>
    <visual>
      <origin rpy="0 0 0" xyz="0 0 0"/>
      <geometry>
        <mesh filename="package://example-robot-data/robots/tiago2_description/meshes/omni_base/wheels/suspension_rear_link.stl" scale="1 1.0 1"/>
      </geometry>
      <material name="">
        <color rgba="0.79216 0.81961 0.93333 1"/>
      </material>
    </visual>
    <collision>
      <origin rpy="0 0 0" xyz="0 0 0"/>
      <geometry>
        <mesh filename="package://example-robot-data/robots/tiago2_description/meshes/omni_base/wheels/suspension_rear_link.stl" scale="1 1.0 1"/>
      </geometry>
    </collision>
    <kinematic>0</kinematic>
    <gravity>1</gravity>
  </link>
  <!-- Changed joint type to fixed joint. It is observed that the robot is loosing contact points due to some issues with the Gazebo Physics Engine. This makes the robot drift in localization when static due to added noise -->
  <joint name="suspension_rear_right_joint" type="fixed">
    <origin rpy="0 0 -1.5707963267948966" xyz="-0.244 -0.1725 0"/>
    <parent link="base_link"/>
    <child link="suspension_rear_right_link"/>
    <axis xyz="0 0 1"/>
  </joint>
  <link name="wheel_rear_right_link">
    <inertial>
      <origin rpy="0 0 0" xyz="-5.4922e-09 -6.9775e-05 0.011144"/>
      <mass value="0.70767"/>
      <inertia ixx="0.00035492" ixy="-7.5685e-13" ixz="3.8795E-11" iyy="0.00035529" iyz="2.0284e-07" izz="0.00040131"/>
    </inertial>
    <visual>
      <origin rpy="0 0 0" xyz="0 0 0"/>
      <geometry>
        <mesh filename="package://example-robot-data/robots/tiago2_description/meshes/omni_base/wheels/wheel_link.stl" scale="1 1 1.0"/>
      </geometry>
      <material name="DarkGrey"/>
    </visual>
    <collision>
      <origin rpy="0 0 0" xyz="0 0 0"/>
      <geometry>
        <cylinder length="0.05" radius="0.0762"/>
      </geometry>
    </collision>
  </link>
  <joint name="wheel_rear_right_joint" type="continuous">
    <origin rpy="-1.5707963267948966 0 1.5707963267948966" xyz="0.050675 0 0"/>
    <parent link="suspension_rear_right_link"/>
    <child link="wheel_rear_right_link"/>
    <axis xyz="0 0 1"/>
    <limit effort="6.0" velocity="13.123359580052492"/>
  </joint>
  <transmission name="wheel_rear_right_trans">
    <type>transmission_interface/SimpleTransmission</type>
    <actuator name="wheel_rear_right_motor">
      <mechanicalReduction>1.0</mechanicalReduction>
    </actuator>
    <joint name="wheel_rear_right_joint">
      <hardwareInterface>hardware_interface/VelocityJointInterface</hardwareInterface>
      <hardwareInterface>hardware_interface/JointStateInterface</hardwareInterface>
    </joint>
  </transmission>
  <!-- Contact model for the wheel surface -->
  <gazebo reference="wheel_rear_right_link">
    <kp>1000000.0</kp>
    <kd>1000.0</kd>
    <mu1>0.0</mu1>
    <mu2>0.0</mu2>
    <fdir1>1 0 0</fdir1>
    <maxVel>1.0</maxVel>
    <minDepth>0.00</minDepth>
    <implicitSpringDamper>1</implicitSpringDamper>
    <material>Gazebo/DarkGrey</material>
  </gazebo>
  <link name="suspension_rear_left_link">
    <inertial>
      <origin rpy="0 0 0" xyz="-0.058182 -0.0043908 -0.0057695"/>
      <mass value="1.2879"/>
      <inertia ixx="0.0015947" ixy="-0.00013183" ixz="1.7315E-05" iyy="0.00060158" iyz="-6.0731e-05" izz="0.0015861"/>
    </inertial>
    <visual>
      <origin rpy="0 0 0" xyz="0 0 0"/>
      <geometry>
        <mesh filename="package://example-robot-data/robots/tiago2_description/meshes/omni_base/wheels/suspension_rear_link.stl" scale="1 -1.0 1"/>
      </geometry>
      <material name="">
        <color rgba="0.79216 0.81961 0.93333 1"/>
      </material>
    </visual>
    <collision>
      <origin rpy="0 0 0" xyz="0 0 0"/>
      <geometry>
        <mesh filename="package://example-robot-data/robots/tiago2_description/meshes/omni_base/wheels/suspension_rear_link.stl" scale="1 -1.0 1"/>
      </geometry>
    </collision>
    <kinematic>0</kinematic>
    <gravity>1</gravity>
  </link>
  <!-- Changed joint type to fixed joint. It is observed that the robot is loosing contact points due to some issues with the Gazebo Physics Engine. This makes the robot drift in localization when static due to added noise -->
  <joint name="suspension_rear_left_joint" type="fixed">
    <origin rpy="0 0 1.5707963267948966" xyz="-0.244 0.1725 0"/>
    <parent link="base_link"/>
    <child link="suspension_rear_left_link"/>
    <axis xyz="0 0 1"/>
  </joint>
  <link name="wheel_rear_left_link">
    <inertial>
      <origin rpy="0 0 0" xyz="-5.4922e-09 6.9775e-05 -0.011144"/>
      <mass value="0.70767"/>
      <inertia ixx="0.00035492" ixy="-7.5685e-13" ixz="3.8795E-11" iyy="0.00035529" iyz="2.0284e-07" izz="0.00040131"/>
    </inertial>
    <visual>
      <origin rpy="0 0 0" xyz="0 0 0"/>
      <geometry>
        <mesh filename="package://example-robot-data/robots/tiago2_description/meshes/omni_base/wheels/wheel_link.stl" scale="1 1 -1.0"/>
      </geometry>
      <material name="DarkGrey"/>
    </visual>
    <collision>
      <origin rpy="0 0 0" xyz="0 0 0"/>
      <geometry>
        <cylinder length="0.05" radius="0.0762"/>
      </geometry>
    </collision>
  </link>
  <joint name="wheel_rear_left_joint" type="continuous">
    <origin rpy="-1.5707963267948966 0 -1.5707963267948966" xyz="0.050675 0 0"/>
    <parent link="suspension_rear_left_link"/>
    <child link="wheel_rear_left_link"/>
    <axis xyz="0 0 1"/>
    <limit effort="6.0" velocity="13.123359580052492"/>
  </joint>
  <transmission name="wheel_rear_left_trans">
    <type>transmission_interface/SimpleTransmission</type>
    <actuator name="wheel_rear_left_motor">
      <mechanicalReduction>1.0</mechanicalReduction>
    </actuator>
    <joint name="wheel_rear_left_joint">
      <hardwareInterface>hardware_interface/VelocityJointInterface</hardwareInterface>
      <hardwareInterface>hardware_interface/JointStateInterface</hardwareInterface>
    </joint>
  </transmission>
  <!-- Contact model for the wheel surface -->
  <gazebo reference="wheel_rear_left_link">
    <kp>1000000.0</kp>
    <kd>1000.0</kd>
    <mu1>0.0</mu1>
    <mu2>0.0</mu2>
    <fdir1>1 0 0</fdir1>
    <maxVel>1.0</maxVel>
    <minDepth>0.00</minDepth>
    <implicitSpringDamper>1</implicitSpringDamper>
    <material>Gazebo/DarkGrey</material>
  </gazebo>
  <!-- Bottom fixed part of column -->
  <link name="torso_fixed_link">
    <inertial>
      <origin rpy="0 0 0" xyz="0.0014857 -0.0077054 0.14693"/>
      <mass value="15.527"/>
      <inertia ixx="0.17904" ixy="0.00019412" ixz="-0.0049479" iyy="0.20082" iyz="0.00015981" izz="0.084141"/>
    </inertial>
    <visual>
      <origin rpy="0 0 0" xyz="0 0 0"/>
      <geometry>
        <mesh filename="package://example-robot-data/robots/tiago2_description/meshes/torso/torso_fixed_link.stl"/>
      </geometry>
      <material name="pal/DarkGrey"/>
    </visual>
    <collision>
      <origin rpy="0 0 0" xyz="0 0 0.1"/>
      <geometry>
        <box size="0.23 0.253 0.2"/>
      </geometry>
      <material name="pal/DarkGrey"/>
    </collision>
    <collision>
      <origin rpy="0 0 0" xyz="0.18 0 0.03"/>
      <geometry>
        <box size="0.15 0.253 0.06"/>
      </geometry>
      <material name="pal/DarkGrey"/>
    </collision>
    <collision>
      <origin rpy="0 0 0" xyz="-0.09 0 0.0"/>
      <geometry>
        <box size="0.47 0.5 0.02"/>
      </geometry>
      <material name="pal/DarkGrey"/>
    </collision>
  </link>
  <gazebo reference="torso_fixed_link">
    <material>Gazebo/DarkGrey</material>
  </gazebo>
  <joint name="torso_fixed_joint" type="fixed">
    <origin rpy="0 0 0" xyz="-0.0245 0 0.215"/>
    <parent link="base_link"/>
    <child link="torso_fixed_link"/>
    <axis xyz="0 0 0"/>
  </joint>
  <!-- Middle extending  -->
  <link name="torso_fixed_column_link">
    <inertial>
      <origin rpy="0 0 0" xyz="0 0 0"/>
      <mass value="0.01"/>
      <inertia ixx="0.000001" ixy="0" ixz="0" iyy="0.000001" iyz="0" izz="0.000001"/>
    </inertial>
    <visual>
      <origin rpy="0 0 0" xyz="0 0 0.275"/>
      <geometry>
        <box size="0.18 0.2 0.55"/>
      </geometry>
      <material name="pal/DarkGrey"/>
    </visual>
    <collision>
      <origin rpy="0 0 0" xyz="0 0 0.275"/>
      <geometry>
        <box size="0.23 0.253 0.45"/>
      </geometry>
      <material name="pal/DarkGrey"/>
    </collision>
  </link>
  <gazebo reference="torso_fixed_column_link">
    <material>Gazebo/DarkGrey</material>
  </gazebo>
  <joint name="torso_fixed_column_joint" type="fixed">
    <origin rpy="0 0 0" xyz="-0.028 0 0.205"/>
    <parent link="base_link"/>
    <child link="torso_fixed_column_link"/>
    <axis xyz="0 0 0"/>
  </joint>
  <link name="torso_lift_link">
    <inertial>
      <origin rpy="0 0 0" xyz="0.0014742 0.0065278 -0.20301"/>
      <mass value="9.547"/>
      <inertia ixx="0.042078" ixy="5.6766E-05" ixz="0.00014731" iyy="0.031115" iyz="-5.0165E-05" izz="0.018659"/>
    </inertial>
    <visual>
      <origin rpy="0 0 0" xyz="0 0 0"/>
      <geometry>
        <mesh filename="package://example-robot-data/robots/tiago2_description/meshes/torso/torso_lift_link.stl"/>
      </geometry>
      <material name="White"/>
    </visual>
    <collision>
      <origin rpy="0 0 0" xyz="0 0 0"/>
      <geometry>
        <mesh filename="package://example-robot-data/robots/tiago2_description/meshes/torso/torso_lift_link_collision.stl"/>
      </geometry>
    </collision>
  </link>
  <joint name="torso_lift_joint" type="prismatic">
    <origin rpy="0.0 0.0 0.0" xyz="0.0 0.0 0.5545"/>
    <parent link="torso_fixed_link"/>
    <child link="torso_lift_link"/>
    <axis xyz="0 0 1"/>
    <limit effort="2000" lower="0" upper="0.35" velocity="0.07"/>
    <calibration rising="0.0"/>
    <dynamics damping="1000"/>
    <safety_controller k_position="20" k_velocity="20" soft_lower_limit="0.0" soft_upper_limit="0.35"/>
  </joint>
  <transmission name="torso_lift_trans">
    <type>transmission_interface/SimpleTransmission</type>
    <actuator name="torso_lift_motor">
      <mechanicalReduction>1.0</mechanicalReduction>
    </actuator>
    <joint name="torso_lift_joint">
      <hardwareInterface>hardware_interface/PositionJointInterface</hardwareInterface>
      <hardwareInterface>hardware_interface/JointStateInterface</hardwareInterface>
    </joint>
  </transmission>
  <gazebo reference="torso_lift_joint">
    <implicitSpringDamper>1</implicitSpringDamper>
  </gazebo>
  <link name="head_1_link">
    <inertial>
      <origin rpy="0 0 0" xyz="0.013723 0.0015288 0.091095"/>
      <mass value="0.50253"/>
      <inertia ixx="0.00073252" ixy="-1.0801E-06" ixz="-6.3715E-05" iyy="0.0005861" iyz="4.157E-10" izz="0.00060232"/>
    </inertial>
    <visual>
      <origin rpy="0 0 0" xyz="0 0 0"/>
      <geometry>
        <mesh filename="package://example-robot-data/robots/tiago2_description/meshes/head/head_1_link.stl" scale="1 1 1"/>
      </geometry>
      <material name="pal/DarkGrey"/>
    </visual>
    <collision>
      <origin rpy="0 0 0.0" xyz="0.0 0 0"/>
      <geometry>
        <mesh filename="package://example-robot-data/robots/tiago2_description/meshes/head/head_1_link_collision.stl" scale="1 1 1"/>
      </geometry>
    </collision>
  </link>
  <joint name="head_1_joint" type="revolute">
    <parent link="torso_lift_link"/>
    <child link="head_1_link"/>
    <origin rpy="0 0 0" xyz="0.0 0.0 0.04"/>
    <axis xyz="0 0 1"/>
    <limit effort="5.197" lower="-0.9599310885968813" upper="0.9599310885968813" velocity="3.0"/>
    <dynamics damping="0.5" friction="1.0"/>
    <safety_controller k_position="20" k_velocity="20" soft_lower_limit="-0.8899310885968812" soft_upper_limit="0.8899310885968812"/>
  </joint>
  <transmission name="head_1_trans">
    <type>transmission_interface/SimpleTransmission</type>
    <actuator name="head_1_motor">
      <mechanicalReduction>1</mechanicalReduction>
    </actuator>
    <joint name="head_1_joint">
      <offset>0.0</offset>
      <hardwareInterface>hardware_interface/JointStateInterface</hardwareInterface>
      <hardwareInterface>hardware_interface/PositionJointInterface</hardwareInterface>
    </joint>
  </transmission>
  <link name="head_2_link">
    <inertial>
      <origin rpy="0 0 0" xyz="0.0025967 0.11474 0.00021233"/>
      <mass value="1.2093"/>
      <inertia ixx="0.0063697" ixy="0.00052067" ixz="-8.4666E-06" iyy="0.0045958" iyz="9.6501E-06" izz="0.0031995"/>
    </inertial>
    <visual>
      <origin rpy="0 0 0" xyz="0 0 0"/>
      <geometry>
        <mesh filename="package://example-robot-data/robots/tiago2_description/meshes/head/head_2_link.stl" scale="1 1 1"/>
      </geometry>
      <material name="White"/>
    </visual>
    <collision>
      <origin rpy="0 0 0" xyz="0 0 0"/>
      <geometry>
        <mesh filename="package://example-robot-data/robots/tiago2_description/meshes/head/head_2_link_collision.stl" scale="1 1 1"/>
      </geometry>
    </collision>
  </link>
  <joint name="head_2_joint" type="revolute">
    <parent link="head_1_link"/>
    <child link="head_2_link"/>
    <origin rpy="1.5708 0 0" xyz="0.04597 0 0.10075"/>
    <axis xyz="0 0 1"/>
    <limit effort="2.77" lower="-0.9599310885968813" upper="0.3490658503988659" velocity="3.0"/>
    <dynamics damping="0.5" friction="1.0"/>
    <safety_controller k_position="20" k_velocity="20" soft_lower_limit="-0.8899310885968812" soft_upper_limit="0.2790658503988659"/>
  </joint>
  <transmission name="head_2_trans">
    <type>transmission_interface/SimpleTransmission</type>
    <actuator name="head_2_motor">
      <mechanicalReduction>1</mechanicalReduction>
    </actuator>
    <joint name="head_2_joint">
      <offset>0.0</offset>
      <hardwareInterface>hardware_interface/JointStateInterface</hardwareInterface>
      <hardwareInterface>hardware_interface/PositionJointInterface</hardwareInterface>
    </joint>
  </transmission>
  <link name="head_screen_link">
    <inertial>
      <origin rpy="0 0 0" xyz="0 0 0"/>
      <mass value="0.0"/>
      <inertia ixx="0.0" ixy="0.0" ixz="0.0" iyy="0.0" iyz="-0.0" izz="0.0"/>
    </inertial>
  </link>
  <joint name="head_screen_joint" type="fixed">
    <parent link="head_2_link"/>
    <child link="head_screen_link"/>
    <origin rpy="-1.5707963267948966 0 0" xyz="0.0528 0.08 0.0"/>
  </joint>
  <gazebo reference="head_1_link">
    <material>Gazebo/DarkGrey</material>
    <mu1>0.9</mu1>
    <mu2>0.9</mu2>
  </gazebo>
  <gazebo reference="head_2_link">
    <material>Gazebo/White</material>
    <mu1>0.9</mu1>
    <mu2>0.9</mu2>
  </gazebo>
  <gazebo reference="head_1_joint">
    <implicitSpringDamper>1</implicitSpringDamper>
  </gazebo>
  <gazebo reference="head_2_joint">
    <implicitSpringDamper>1</implicitSpringDamper>
  </gazebo>
  <material name="head_d435_camera_aluminum">
    <color rgba="0.5 0.5 0.5 1"/>
  </material>
  <!-- camera body, with origin at bottom screw mount -->
  <joint name="head_d435_camera_joint" type="fixed">
    <origin rpy="-1.5707963267948966 0.0 0.0" xyz="0.03815 0.14750 0.0"/>
    <parent link="head_2_link"/>
    <child link="head_d435_camera_bottom_screw_frame"/>
  </joint>
  <link name="head_d435_camera_bottom_screw_frame">
    <inertial>
      <origin rpy="0 0 0" xyz="0 0 0"/>
      <mass value="0.0"/>
      <inertia ixx="0.0" ixy="0.0" ixz="0.0" iyy="0.0" iyz="-0.0" izz="0.0"/>
    </inertial>
  </link>
  <joint name="head_d435_camera_link_joint" type="fixed">
    <origin rpy="0 0 0" xyz="0.010600000000000002 0.0175 0.0125"/>
    <parent link="head_d435_camera_bottom_screw_frame"/>
    <child link="head_d435_camera_link"/>
  </joint>
  <link name="head_d435_camera_link">
    <visual>
      <!-- the mesh origin is at front plate in between the two infrared camera axes -->
      <origin rpy="1.5707963267948966 0 1.5707963267948966" xyz="0.0043 -0.0175 0"/>
      <geometry>
        <box size="0.02505 0.09 0.025"/>
        <!-- <mesh filename="package://realsense2_description/meshes/d435.dae"/> -->
      </geometry>
    </visual>
    <collision>
      <origin rpy="0 0 0" xyz="0 -0.0175 0"/>
      <geometry>
        <box size="0.02505 0.09 0.025"/>
      </geometry>
    </collision>
    <inertial>
      <!-- The following are not reliable values, and should not be used for modeling -->
      <mass value="0.072"/>
      <origin xyz="0 0 0"/>
      <inertia ixx="0.003881243" ixy="0.0" ixz="0.0" iyy="0.000498940" iyz="0.0" izz="0.003879257"/>
    </inertial>
  </link>
  <!-- camera depth joints and links -->
  <joint name="head_d435_camera_depth_joint" type="fixed">
    <origin rpy="0 0 0" xyz="0 0 0"/>
    <parent link="head_d435_camera_link"/>
    <child link="head_d435_camera_depth_frame"/>
  </joint>
  <link name="head_d435_camera_depth_frame">
        <inertial>
      <origin rpy="0 0 0" xyz="0 0 0"/>
      <mass value="0.0"/>
      <inertia ixx="0.0" ixy="0.0" ixz="0.0" iyy="0.0" iyz="-0.0" izz="0.0"/>
    </inertial>
  </link>
  <joint name="head_d435_camera_depth_optical_joint" type="fixed">
    <origin rpy="-1.5707963267948966 0 -1.5707963267948966" xyz="0 0 0"/>
    <parent link="head_d435_camera_depth_frame"/>
    <child link="head_d435_camera_depth_optical_frame"/>
  </joint>
  <link name="head_d435_camera_depth_optical_frame">
        <inertial>
      <origin rpy="0 0 0" xyz="0 0 0"/>
      <mass value="0.0"/>
      <inertia ixx="0.0" ixy="0.0" ixz="0.0" iyy="0.0" iyz="-0.0" izz="0.0"/>
    </inertial>
  </link>
  <!-- camera left IR joints and links -->
  <joint name="head_d435_camera_infra1_joint" type="fixed">
    <origin rpy="0 0 0" xyz="0 0.0 0"/>
    <parent link="head_d435_camera_link"/>
    <child link="head_d435_camera_infra1_frame"/>
  </joint>
  <link name="head_d435_camera_infra1_frame">
        <inertial>
      <origin rpy="0 0 0" xyz="0 0 0"/>
      <mass value="0.0"/>
      <inertia ixx="0.0" ixy="0.0" ixz="0.0" iyy="0.0" iyz="-0.0" izz="0.0"/>
    </inertial>
  </link>
  <joint name="head_d435_camera_infra1_optical_joint" type="fixed">
    <origin rpy="-1.5707963267948966 0 -1.5707963267948966" xyz="0 0 0"/>
    <parent link="head_d435_camera_infra1_frame"/>
    <child link="head_d435_camera_infra1_optical_frame"/>
  </joint>
  <link name="head_d435_camera_infra1_optical_frame">
        <inertial>
      <origin rpy="0 0 0" xyz="0 0 0"/>
      <mass value="0.0"/>
      <inertia ixx="0.0" ixy="0.0" ixz="0.0" iyy="0.0" iyz="-0.0" izz="0.0"/>
    </inertial>
  </link>
  <!-- camera right IR joints and links -->
  <joint name="head_d435_camera_infra2_joint" type="fixed">
    <origin rpy="0 0 0" xyz="0 -0.05 0"/>
    <parent link="head_d435_camera_link"/>
    <child link="head_d435_camera_infra2_frame"/>
  </joint>
  <link name="head_d435_camera_infra2_frame">
        <inertial>
      <origin rpy="0 0 0" xyz="0 0 0"/>
      <mass value="0.0"/>
      <inertia ixx="0.0" ixy="0.0" ixz="0.0" iyy="0.0" iyz="-0.0" izz="0.0"/>
    </inertial>
  </link>
  <joint name="head_d435_camera_infra2_optical_joint" type="fixed">
    <origin rpy="-1.5707963267948966 0 -1.5707963267948966" xyz="0 0 0"/>
    <parent link="head_d435_camera_infra2_frame"/>
    <child link="head_d435_camera_infra2_optical_frame"/>
  </joint>
  <link name="head_d435_camera_infra2_optical_frame">
    <inertial>
      <origin rpy="0 0 0" xyz="0 0 0"/>
      <mass value="0.0"/>
      <inertia ixx="0.0" ixy="0.0" ixz="0.0" iyy="0.0" iyz="-0.0" izz="0.0"/>
    </inertial>
  </link>

  <!-- camera color joints and links -->
  <joint name="head_d435_camera_color_joint" type="fixed">
    <origin rpy="0 0 0" xyz="0 0.015 0"/>
    <parent link="head_d435_camera_link"/>
    <child link="head_d435_camera_color_frame"/>
  </joint>
  <link name="head_d435_camera_color_frame">
        <inertial>
      <origin rpy="0 0 0" xyz="0 0 0"/>
      <mass value="0.0"/>
      <inertia ixx="0.0" ixy="0.0" ixz="0.0" iyy="0.0" iyz="-0.0" izz="0.0"/>
    </inertial>
  </link>
  <joint name="head_d435_camera_color_optical_joint" type="fixed">
    <origin rpy="-1.5707963267948966 0 -1.5707963267948966" xyz="0 0 0"/>
    <parent link="head_d435_camera_color_frame"/>
    <child link="head_d435_camera_color_optical_frame"/>
  </joint>
  <link name="head_d435_camera_color_optical_frame">
        <inertial>
      <origin rpy="0 0 0" xyz="0 0 0"/>
      <mass value="0.0"/>
      <inertia ixx="0.0" ixy="0.0" ixz="0.0" iyy="0.0" iyz="-0.0" izz="0.0"/>
    </inertial>
  </link>
  <gazebo reference="head_d435_camera_link">
    <self_collide>0</self_collide>
    <enable_wind>0</enable_wind>
    <kinematic>0</kinematic>
    <gravity>1</gravity>
    <!--<mu>1</mu>-->
    <mu2>1</mu2>
    <fdir1>0 0 0</fdir1>
    <!--<slip1>0</slip1>
      <slip2>0</slip2>-->
    <kp>1e+13</kp>
    <kd>1</kd>
    <!--<max_vel>0.01</max_vel>
      <min_depth>0</min_depth>-->
    <sensor name="head_d435_cameracolor" type="camera">
      <camera name="head_d435_camera">
        <horizontal_fov>1.2112585008840648</horizontal_fov>
        <image>
          <width>640</width>
          <height>480</height>
          <format>RGB_INT8</format>
        </image>
        <clip>
          <near>0.1</near>
          <far>100</far>
        </clip>
        <noise>
          <type>gaussian</type>
          <mean>0.0</mean>
          <stddev>0.007</stddev>
        </noise>
      </camera>
      <always_on>1</always_on>
      <update_rate>30</update_rate>
      <visualize>1</visualize>
    </sensor>
    <sensor name="head_d435_cameraired1" type="camera">
      <camera name="head_d435_camera">
        <horizontal_fov>1.4870205226991688</horizontal_fov>
        <image>
          <width>1280</width>
          <height>720</height>
          <format>L_INT8</format>
        </image>
        <clip>
          <near>0.1</near>
          <far>100</far>
        </clip>
        <noise>
          <type>gaussian</type>
          <mean>0.0</mean>
          <stddev>0.05</stddev>
        </noise>
      </camera>
      <always_on>1</always_on>
      <update_rate>90</update_rate>
      <visualize>0</visualize>
    </sensor>
    <sensor name="head_d435_cameraired2" type="camera">
      <camera name="head_d435_camera">
        <horizontal_fov>1.4870205226991688</horizontal_fov>
        <image>
          <width>1280</width>
          <height>720</height>
          <format>L_INT8</format>
        </image>
        <clip>
          <near>0.1</near>
          <far>100</far>
        </clip>
        <noise>
          <type>gaussian</type>
          <mean>0.0</mean>
          <stddev>0.05</stddev>
        </noise>
      </camera>
      <always_on>1</always_on>
      <update_rate>90</update_rate>
      <visualize>0</visualize>
    </sensor>
    <sensor name="head_d435_cameradepth" type="depth">
      <camera name="head_d435_camera">
        <horizontal_fov>1.4870205226991688</horizontal_fov>
        <image>
          <width>1280</width>
          <height>720</height>
        </image>
        <clip>
          <near>0.1</near>
          <far>100</far>
        </clip>
        <noise>
          <type>gaussian</type>
          <mean>0.0</mean>
          <stddev>0.100</stddev>
        </noise>
      </camera>
      <always_on>1</always_on>
      <update_rate>90</update_rate>
      <visualize>0</visualize>
    </sensor>
  </gazebo>
  <gazebo>
    <plugin filename="librealsense_gazebo_plugin.so" name="head_d435_camera">
      <prefix>head_d435_camera</prefix>
      <depthUpdateRate>30.0</depthUpdateRate>
      <colorUpdateRate>30.0</colorUpdateRate>
      <infraredUpdateRate>30.0</infraredUpdateRate>
      <depthTopicName>depth/image_raw</depthTopicName>
      <depthCameraInfoTopicName>depth/camera_info</depthCameraInfoTopicName>
      <colorTopicName>color/image_raw</colorTopicName>
      <colorCameraInfoTopicName>color/camera_info</colorCameraInfoTopicName>
      <infrared1TopicName>infra1/image_raw</infrared1TopicName>
      <infrared1CameraInfoTopicName>infra1/camera_info</infrared1CameraInfoTopicName>
      <infrared2TopicName>infra2/image_raw</infrared2TopicName>
      <infrared2CameraInfoTopicName>infra2/camera_info</infrared2CameraInfoTopicName>
      <colorOpticalframeName>head_d435_camera_color_optical_frame</colorOpticalframeName>
      <depthOpticalframeName>head_d435_camera_depth_optical_frame</depthOpticalframeName>
      <infrared1OpticalframeName>head_d435_camera_infra1_ir_optical_frame</infrared1OpticalframeName>
      <infrared2OpticalframeName>head_d435_camera_infra2_ir_optical_frame</infrared2OpticalframeName>
      <rangeMinDepth>0.2</rangeMinDepth>
      <rangeMaxDepth>10.0</rangeMaxDepth>
      <pointCloud>True</pointCloud>
      <pointCloudTopicName>depth/color/points</pointCloudTopicName>
      <pointCloudCutoff>0.25</pointCloudCutoff>
      <pointCloudCutoffMax>9.0</pointCloudCutoffMax>
    </plugin>
  </gazebo>
  <!-- ARM 1 LINK -->
  <link name="arm_left_1_link">
    <inertial>
      <origin rpy="0 0 0" xyz="0.0023908 0.015901 0.1545"/>
      <mass value="1.0816"/>
      <inertia ixx="0.0024426" ixy="2.3307E-05" ixz="5.9333E-05" iyy="0.0023089" iyz="-0.00020369" izz="0.00092843"/>
    </inertial>
    <visual>
      <origin rpy="0 0 0" xyz="0 0 0"/>
      <geometry>
        <mesh filename="package://example-robot-data/robots/tiago2_description/meshes/arm_tiago_pro/arm_1_link.stl" scale="1 1 1"/>
      </geometry>
      <material name="pal/DarkGrey"/>
    </visual>
    <collision>
      <origin rpy="0 0 0" xyz="0 0 0"/>
      <geometry>
        <mesh filename="package://example-robot-data/robots/tiago2_description/meshes/arm_tiago_pro/arm_1_link_collision.stl" scale="1 1 1"/>
      </geometry>
    </collision>
  </link>
  <!-- ARM 1 JOINT -->
  <joint name="arm_left_1_joint" type="revolute">
    <origin rpy="-2.0679 0.0 -1.2217" xyz="0.08976 0.15918 -0.092008"/>
    <parent link="torso_lift_link"/>
    <child link="arm_left_1_link"/>
    <axis xyz="0 0 1"/>
    <limit effort="43.0" lower="-2.6000169866959526" upper="2.6000169866959526" velocity="1.95"/>
    <dynamics damping="1.0" friction="1.0"/>
    <safety_controller k_position="20" k_velocity="20" soft_lower_limit="-148.9" soft_upper_limit="148.9"/>
  </joint>
  <!-- ARM 2 LINK -->
  <link name="arm_left_2_link">
    <inertial>
      <origin rpy="0 0 0" xyz="-0.11649 -0.017864 0.0053772"/>
      <mass value="0.99204"/>
      <inertia ixx="0.00077294" ixy="-0.00011001" ixz="-0.00016136" iyy="0.0014605" iyz="-1.3224E-05" izz="0.0015605"/>
    </inertial>
    <visual>
      <origin rpy="0 0 0" xyz="0 0 0"/>
      <geometry>
        <mesh filename="package://example-robot-data/robots/tiago2_description/meshes/arm_tiago_pro/arm_2_link.stl" scale="1 1 1"/>
      </geometry>
      <material name="pal/DarkGrey"/>
    </visual>
    <collision>
      <origin rpy="0 0 0" xyz="0 0 0"/>
      <geometry>
        <mesh filename="package://example-robot-data/robots/tiago2_description/meshes/arm_tiago_pro/arm_2_link_collision.stl" scale="1 1 1"/>
      </geometry>
    </collision>
  </link>
  <!-- ARM 2 JOINT -->
  <joint name="arm_left_2_joint" type="revolute">
    <origin rpy="0 1.5708 0" xyz="0.0 0.02 0.18"/>
    <parent link="arm_left_1_link"/>
    <child link="arm_left_2_link"/>
    <axis xyz="0 0 1"/>
    <limit effort="43.0" lower="-2.4399702942880728" upper="1.1000810275320259" velocity="1.95"/>
    <dynamics damping="1.0" friction="1.0"/>
    <safety_controller k_position="20" k_velocity="20" soft_lower_limit="-2.369970294288073" soft_upper_limit="1.0300810275320258"/>
  </joint>
  <!-- ARM 3 LINK -->
  <link name="arm_left_3_link">
    <inertial>
      <origin rpy="0 0 0" xyz="0.0023908 0.015901 0.1545"/>
      <mass value="1.0816"/>
      <inertia ixx="0.0024426" ixy="2.3307E-05" ixz="5.9333E-05" iyy="0.0023089" iyz="-0.00020369" izz="0.00092843"/>
    </inertial>
    <visual>
      <origin rpy="0 0 0" xyz="0 0 0"/>
      <geometry>
        <mesh filename="package://example-robot-data/robots/tiago2_description/meshes/arm_tiago_pro/arm_3_link.stl" scale="1 1 1"/>
      </geometry>
      <material name="pal/DarkGrey"/>
    </visual>
    <collision>
      <origin rpy="0 0 0" xyz="0 0 0"/>
      <geometry>
        <mesh filename="package://example-robot-data/robots/tiago2_description/meshes/arm_tiago_pro/arm_3_link_collision.stl" scale="1 1 1"/>
      </geometry>
    </collision>
  </link>
  <!-- ARM 3 JOINT -->
  <joint name="arm_left_3_joint" type="revolute">
    <origin rpy="3.1415 1.5707 0" xyz="-0.15 -0.02 0"/>
    <parent link="arm_left_2_link"/>
    <child link="arm_left_3_link"/>
    <axis xyz="0 0 1"/>
    <limit effort="26" lower="-2.6000169866959526" upper="2.6000169866959526" velocity="2.35"/>
    <dynamics damping="1.0" friction="1.0"/>
    <safety_controller k_position="20" k_velocity="20" soft_lower_limit="-2.5300169866959528" soft_upper_limit="2.5300169866959528"/>
  </joint>
  <!-- ARM 4 LINK -->
  <link name="arm_left_4_link">
    <inertial>
      <origin rpy="0 0 0" xyz="-0.11649 -0.017864 0.0053772"/>
      <mass value="0.99204"/>
      <inertia ixx="0.00077294" ixy="-0.00011001" ixz="-0.00016136" iyy="0.0014605" iyz="-1.3224E-05" izz="0.0015605"/>
    </inertial>
    <visual>
      <origin rpy="0 0 0" xyz="0 0 0"/>
      <geometry>
        <mesh filename="package://example-robot-data/robots/tiago2_description/meshes/arm_tiago_pro/arm_4_link.stl" scale="1 1 1"/>
      </geometry>
      <material name="pal/DarkGrey"/>
    </visual>
    <collision>
      <origin rpy="0 0 0" xyz="0 0 0"/>
      <geometry>
        <mesh filename="package://example-robot-data/robots/tiago2_description/meshes/arm_tiago_pro/arm_4_link_collision.stl" scale="1 1 1"/>
      </geometry>
    </collision>
  </link>
  <!-- ARM 4 JOINT -->
  <joint name="arm_left_4_joint" type="revolute">
    <origin rpy="0 1.5708 0" xyz="0 0.02 0.18"/>
    <parent link="arm_left_3_link"/>
    <child link="arm_left_4_link"/>
    <axis xyz="0 0 1"/>
    <limit effort="26" lower="-2.4399702942880728" upper="1.1000810275320259" velocity="2.35"/>
    <dynamics damping="1.0" friction="1.0"/>
    <safety_controller k_position="20" k_velocity="20" soft_lower_limit="-2.369970294288073" soft_upper_limit="1.0300810275320258"/>
  </joint>
  <!-- ARM 5 LINK -->
  <link name="arm_left_5_link">
    <inertial>
      <origin rpy="0 0 0" xyz="0.0004859 0.00014289 0.129"/>
      <mass value="0.52538"/>
      <inertia ixx="0.0019111" ixy="-1.4245E-08" ixz="3.8663E-05" iyy="0.0018565" iyz="1.1356E-06" izz="0.00046496"/>
    </inertial>
    <visual>
      <origin rpy="0 0 0" xyz="0 0 0"/>
      <geometry>
        <mesh filename="package://example-robot-data/robots/tiago2_description/meshes/arm_tiago_pro/arm_5_link.stl" scale="1 1 1"/>
      </geometry>
      <material name="pal/DarkGrey"/>
    </visual>
    <collision>
      <origin rpy="0 0 0" xyz="0 0 0"/>
      <geometry>
        <mesh filename="package://example-robot-data/robots/tiago2_description/meshes/arm_tiago_pro/arm_5_link_collision.stl" scale="1 1 1"/>
      </geometry>
    </collision>
  </link>
  <!-- ARM 5 JOINT -->
  <joint name="arm_left_5_joint" type="revolute">
    <origin rpy="0 -1.5708 0" xyz="-0.15 -0.02 0"/>
    <parent link="arm_left_4_link"/>
    <child link="arm_left_5_link"/>
    <axis xyz="0 0 1"/>
    <limit effort="26" lower="-2.6000169866959526" upper="2.6000169866959526" velocity="2.35"/>
    <dynamics damping="1.0" friction="1.0"/>
    <safety_controller k_position="20" k_velocity="20" soft_lower_limit="-2.5300169866959528" soft_upper_limit="2.5300169866959528"/>
  </joint>
  <!-- ARM 6 LINK -->
  <link name="arm_left_6_link">
    <inertial>
      <origin rpy="0 0 0" xyz="-0.086822 -7.7905E-06 0.0045258"/>
      <mass value="0.66725"/>
      <inertia ixx="0.00035696" ixy="1.6019E-07" ixz="-9.5191E-05" iyy="0.00073846" iyz="2.118E-08" izz="0.00075321"/>
    </inertial>
    <visual>
      <origin rpy="0 0 0" xyz="0 0 0"/>
      <geometry>
        <mesh filename="package://example-robot-data/robots/tiago2_description/meshes/arm_tiago_pro/arm_6_link.stl" scale="1 1 1"/>
      </geometry>
      <material name="pal/DarkGrey"/>
    </visual>
    <collision>
      <origin rpy="0 0 0" xyz="0 0 0"/>
      <geometry>
        <mesh filename="package://example-robot-data/robots/tiago2_description/meshes/arm_tiago_pro/arm_6_link_collision.stl" scale="1 1 1"/>
      </geometry>
    </collision>
  </link>
  <!-- ARM 6 JOINT -->
  <joint name="arm_left_6_joint" type="revolute">
    <origin rpy="0 1.5708 0" xyz="0 0 0.185"/>
    <parent link="arm_left_5_link"/>
    <child link="arm_left_6_link"/>
    <axis xyz="0 0 1"/>
    <limit effort="26" lower="-1.9999727898603024" upper="1.9999727898603024" velocity="2.35"/>
    <dynamics damping="1.0" friction="1.0"/>
    <safety_controller k_position="20" k_velocity="20" soft_lower_limit="-1.9299727898603023" soft_upper_limit="1.9299727898603023"/>
  </joint>
  <!-- ARM 7 LINK -->
  <link name="arm_left_7_link">
    <inertial>
      <origin rpy="0 0 0" xyz="-6.764E-18 -1.4549E-16 0.018549"/>
      <mass value="0.10189"/>
      <inertia ixx="5.1076E-05" ixy="-1.0899E-21" ixz="-5.93E-21" iyy="5.0882E-05" iyz="-8.5344E-21" izz="9.705E-05"/>
    </inertial>
    <visual>
      <origin rpy="0 0 0" xyz="0 0 0"/>
      <geometry>
        <mesh filename="package://example-robot-data/robots/tiago2_description/meshes/arm_tiago_pro/arm_7_link.stl" scale="1 1 1"/>
      </geometry>
      <material name="pal/DarkGrey"/>
    </visual>
    <collision>
      <origin rpy="0 0 0" xyz="0 0 0"/>
      <geometry>
        <mesh filename="package://example-robot-data/robots/tiago2_description/meshes/arm_tiago_pro/arm_7_link_collision.stl" scale="1 1 1"/>
      </geometry>
    </collision>
  </link>
  <!-- ARM 7 JOINT -->
  <joint name="arm_left_7_joint" type="revolute">
    <origin rpy="0 -1.5708 0" xyz="-0.1166 0 0"/>
    <parent link="arm_left_6_link"/>
    <child link="arm_left_7_link"/>
    <axis xyz="0 0 1"/>
    <limit effort="26" lower="-2.6000169866959526" upper="2.6000169866959526" velocity="2.35"/>
    <dynamics damping="1.0" friction="1.0"/>
    <safety_controller k_position="20" k_velocity="20" soft_lower_limit="-2.5300169866959528" soft_upper_limit="2.5300169866959528"/>
  </joint>
  <!--***********************-->
  <!--        TOOL           -->
  <!--***********************-->
  <link name="arm_left_tool_link">
    <inertial>
      <origin rpy="0 0 0" xyz="5.0493E-18 -4.4892E-17 -0.0068514"/>
      <mass value="0.10189"/>
      <inertia ixx="5.1076E-05" ixy="-1.0374E-21" ixz="-5.9164E-21" iyy="5.0882E-05" iyz="-8.5211E-21" izz="9.705E-05"/>
    </inertial>
    <visual>
      <origin rpy="0 1.5707963267948966 0" xyz="0.001 0 0"/>
      <geometry>
        <cylinder length="0.01" radius="0.032"/>
      </geometry>
      <material name="pal/DarkGrey"/>
    </visual>
    <collision>
      <origin rpy="0 1.5707963267948966 0" xyz="0.001 0 0"/>
      <geometry>
        <cylinder length="0.01" radius="0.032"/>
      </geometry>
    </collision>
  </link>
  <joint name="arm_left_tool_joint" type="fixed">
    <parent link="arm_left_7_link"/>
    <child link="arm_left_tool_link"/>
    <origin rpy="0 -1.5707963267948966 1.5707963267948966" xyz="0 0 0.0184"/>
  </joint>
  <gazebo reference="arm_left_1_link">
    <material>Gazebo/DarkGrey</material>
    <mu1>0.9</mu1>
    <mu2>0.9</mu2>
  </gazebo>
  <gazebo reference="arm_left_2_link">
    <material>Gazebo/DarkGrey</material>
    <mu1>0.9</mu1>
    <mu2>0.9</mu2>
  </gazebo>
  <gazebo reference="arm_left_3_link">
    <material>Gazebo/DarkGrey</material>
    <mu1>0.9</mu1>
    <mu2>0.9</mu2>
  </gazebo>
  <gazebo reference="arm_left_4_link">
    <material>Gazebo/DarkGrey</material>
    <mu1>0.9</mu1>
    <mu2>0.9</mu2>
  </gazebo>
  <gazebo reference="arm_left_5_link">
    <material>Gazebo/DarkGrey</material>
    <mu1>0.9</mu1>
    <mu2>0.9</mu2>
  </gazebo>
  <gazebo reference="arm_left_6_link">
    <material>Gazebo/DarkGrey</material>
    <mu1>0.9</mu1>
    <mu2>0.9</mu2>
  </gazebo>
  <gazebo reference="arm_left_7_link">
    <material>Gazebo/DarkGrey</material>
    <mu1>0.9</mu1>
    <mu2>0.9</mu2>
  </gazebo>
  <gazebo reference="arm_left_1_joint">
    <implicitSpringDamper>1</implicitSpringDamper>
  </gazebo>
  <gazebo reference="arm_left_2_joint">
    <implicitSpringDamper>1</implicitSpringDamper>
  </gazebo>
  <gazebo reference="arm_left_3_joint">
    <implicitSpringDamper>1</implicitSpringDamper>
  </gazebo>
  <gazebo reference="arm_left_4_joint">
    <implicitSpringDamper>1</implicitSpringDamper>
  </gazebo>
  <gazebo reference="arm_left_5_joint">
    <implicitSpringDamper>1</implicitSpringDamper>
  </gazebo>
  <gazebo reference="arm_left_6_joint">
    <implicitSpringDamper>1</implicitSpringDamper>
  </gazebo>
  <gazebo reference="arm_left_7_joint">
    <implicitSpringDamper>1</implicitSpringDamper>
    <provideFeedback>1</provideFeedback>
  </gazebo>
  <transmission name="arm_left_1_trans">
    <type>sea_transmissions/SeaSimpleTransmission</type>
    <actuator name="arm_left_1_motor">
      <mechanicalReduction>121.0</mechanicalReduction>
    </actuator>
    <joint name="arm_left_1_joint">
      <actuators_data_ns>/actuators_data/arm_left_1_motor</actuators_data_ns>
      <joint_offset_ns>/arm_left_1_motor/output_offset</joint_offset_ns>
      <hardwareInterface>hardware_interface/PositionJointInterface</hardwareInterface>
      <hardwareInterface>hardware_interface/VelocityJointInterface</hardwareInterface>
      <hardwareInterface>hardware_interface/EffortJointInterface</hardwareInterface>
      <hardwareInterface>hardware_interface/JointStateInterface</hardwareInterface>
    </joint>
  </transmission>
  <transmission name="arm_left_2_trans">
    <type>sea_transmissions/SeaSimpleTransmission</type>
    <actuator name="arm_left_2_motor">
      <mechanicalReduction>121.0</mechanicalReduction>
    </actuator>
    <joint name="arm_left_2_joint">
      <actuators_data_ns>/actuators_data/arm_left_2_motor</actuators_data_ns>
      <joint_offset_ns>/arm_left_2_motor/output_offset</joint_offset_ns>
      <hardwareInterface>hardware_interface/PositionJointInterface</hardwareInterface>
      <hardwareInterface>hardware_interface/VelocityJointInterface</hardwareInterface>
      <hardwareInterface>hardware_interface/EffortJointInterface</hardwareInterface>
      <hardwareInterface>hardware_interface/JointStateInterface</hardwareInterface>
    </joint>
  </transmission>
  <transmission name="arm_left_3_trans">
    <type>sea_transmissions/SeaSimpleTransmission</type>
    <actuator name="arm_left_3_motor">
      <mechanicalReduction>101.0</mechanicalReduction>
    </actuator>
    <joint name="arm_left_3_joint">
      <actuators_data_ns>/actuators_data/arm_left_3_motor</actuators_data_ns>
      <joint_offset_ns>/arm_left_3_motor/output_offset</joint_offset_ns>
      <hardwareInterface>hardware_interface/PositionJointInterface</hardwareInterface>
      <hardwareInterface>hardware_interface/VelocityJointInterface</hardwareInterface>
      <hardwareInterface>hardware_interface/EffortJointInterface</hardwareInterface>
      <hardwareInterface>hardware_interface/JointStateInterface</hardwareInterface>
    </joint>
  </transmission>
  <transmission name="arm_left_4_trans">
    <type>sea_transmissions/SeaSimpleTransmission</type>
    <actuator name="arm_left_4_motor">
      <mechanicalReduction>101.0</mechanicalReduction>
    </actuator>
    <joint name="arm_left_4_joint">
      <actuators_data_ns>/actuators_data/arm_left_4_motor</actuators_data_ns>
      <joint_offset_ns>/arm_left_4_motor/output_offset</joint_offset_ns>
      <hardwareInterface>hardware_interface/PositionJointInterface</hardwareInterface>
      <hardwareInterface>hardware_interface/VelocityJointInterface</hardwareInterface>
      <hardwareInterface>hardware_interface/EffortJointInterface</hardwareInterface>
      <hardwareInterface>hardware_interface/JointStateInterface</hardwareInterface>
    </joint>
  </transmission>
  <transmission name="arm_left_5_trans">
    <type>sea_transmissions/SeaSimpleTransmission</type>
    <actuator name="arm_left_5_motor">
      <mechanicalReduction>101.0</mechanicalReduction>
    </actuator>
    <joint name="arm_left_5_joint">
      <actuators_data_ns>/actuators_data/arm_left_5_motor</actuators_data_ns>
      <joint_offset_ns>/arm_left_5_motor/output_offset</joint_offset_ns>
      <hardwareInterface>hardware_interface/PositionJointInterface</hardwareInterface>
      <hardwareInterface>hardware_interface/VelocityJointInterface</hardwareInterface>
      <hardwareInterface>hardware_interface/EffortJointInterface</hardwareInterface>
      <hardwareInterface>hardware_interface/JointStateInterface</hardwareInterface>
    </joint>
  </transmission>
  <transmission name="arm_left_6_trans">
    <type>sea_transmissions/SeaSimpleTransmission</type>
    <actuator name="arm_left_6_motor">
      <mechanicalReduction>101.0</mechanicalReduction>
    </actuator>
    <joint name="arm_left_6_joint">
      <actuators_data_ns>/actuators_data/arm_left_6_motor</actuators_data_ns>
      <joint_offset_ns>/arm_left_6_motor/output_offset</joint_offset_ns>
      <hardwareInterface>hardware_interface/PositionJointInterface</hardwareInterface>
      <hardwareInterface>hardware_interface/VelocityJointInterface</hardwareInterface>
      <hardwareInterface>hardware_interface/EffortJointInterface</hardwareInterface>
      <hardwareInterface>hardware_interface/JointStateInterface</hardwareInterface>
    </joint>
  </transmission>
  <transmission name="arm_left_7_trans">
    <type>sea_transmissions/SeaSimpleTransmission</type>
    <actuator name="arm_left_7_motor">
      <mechanicalReduction>101.0</mechanicalReduction>
    </actuator>
    <joint name="arm_left_7_joint">
      <actuators_data_ns>/actuators_data/arm_left_7_motor</actuators_data_ns>
      <joint_offset_ns>/arm_left_7_motor/output_offset</joint_offset_ns>
      <hardwareInterface>hardware_interface/PositionJointInterface</hardwareInterface>
      <hardwareInterface>hardware_interface/VelocityJointInterface</hardwareInterface>
      <hardwareInterface>hardware_interface/EffortJointInterface</hardwareInterface>
      <hardwareInterface>hardware_interface/JointStateInterface</hardwareInterface>
    </joint>
  </transmission>
  <!-- ARM 1 LINK -->
  <link name="arm_right_1_link">
    <inertial>
      <origin rpy="0 0 0" xyz="0.0023908 0.015901 0.1545"/>
      <mass value="1.0816"/>
      <inertia ixx="0.0024426" ixy="2.3307E-05" ixz="5.9333E-05" iyy="0.0023089" iyz="-0.00020369" izz="0.00092843"/>
    </inertial>
    <visual>
      <origin rpy="0 0 0" xyz="0 0 0"/>
      <geometry>
        <mesh filename="package://example-robot-data/robots/tiago2_description/meshes/arm_tiago_pro/arm_1_link.stl" scale="1 1 1"/>
      </geometry>
      <material name="pal/DarkGrey"/>
    </visual>
    <collision>
      <origin rpy="0 0 0" xyz="0 0 0"/>
      <geometry>
        <mesh filename="package://example-robot-data/robots/tiago2_description/meshes/arm_tiago_pro/arm_1_link_collision.stl" scale="1 1 1"/>
      </geometry>
    </collision>
  </link>
  <!-- ARM 1 JOINT -->
  <joint name="arm_right_1_joint" type="revolute">
    <origin rpy="-2.0679 -0.0 -1.9198899999999999" xyz="0.08976 -0.15918 -0.092008"/>
    <parent link="torso_lift_link"/>
    <child link="arm_right_1_link"/>
    <axis xyz="0 0 1"/>
    <limit effort="43.0" lower="-2.6000169866959526" upper="2.6000169866959526" velocity="1.95"/>
    <dynamics damping="1.0" friction="1.0"/>
    <safety_controller k_position="20" k_velocity="20" soft_lower_limit="-148.9" soft_upper_limit="148.9"/>
  </joint>
  <!-- ARM 2 LINK -->
  <link name="arm_right_2_link">
    <inertial>
      <origin rpy="0 0 0" xyz="-0.11649 -0.017864 0.0053772"/>
      <mass value="0.99204"/>
      <inertia ixx="0.00077294" ixy="-0.00011001" ixz="-0.00016136" iyy="0.0014605" iyz="-1.3224E-05" izz="0.0015605"/>
    </inertial>
    <visual>
      <origin rpy="0 0 0" xyz="0 0 0"/>
      <geometry>
        <mesh filename="package://example-robot-data/robots/tiago2_description/meshes/arm_tiago_pro/arm_2_link.stl" scale="1 1 1"/>
      </geometry>
      <material name="pal/DarkGrey"/>
    </visual>
    <collision>
      <origin rpy="0 0 0" xyz="0 0 0"/>
      <geometry>
        <mesh filename="package://example-robot-data/robots/tiago2_description/meshes/arm_tiago_pro/arm_2_link_collision.stl" scale="1 1 1"/>
      </geometry>
    </collision>
  </link>
  <!-- ARM 2 JOINT -->
  <joint name="arm_right_2_joint" type="revolute">
    <origin rpy="0 1.5708 0" xyz="0.0 0.02 0.18"/>
    <parent link="arm_right_1_link"/>
    <child link="arm_right_2_link"/>
    <axis xyz="0 0 1"/>
    <limit effort="43.0" lower="-2.4399702942880728" upper="1.1000810275320259" velocity="1.95"/>
    <dynamics damping="1.0" friction="1.0"/>
    <safety_controller k_position="20" k_velocity="20" soft_lower_limit="-2.369970294288073" soft_upper_limit="1.0300810275320258"/>
  </joint>
  <!-- ARM 3 LINK -->
  <link name="arm_right_3_link">
    <inertial>
      <origin rpy="0 0 0" xyz="0.0023908 0.015901 0.1545"/>
      <mass value="1.0816"/>
      <inertia ixx="0.0024426" ixy="2.3307E-05" ixz="5.9333E-05" iyy="0.0023089" iyz="-0.00020369" izz="0.00092843"/>
    </inertial>
    <visual>
      <origin rpy="0 0 0" xyz="0 0 0"/>
      <geometry>
        <mesh filename="package://example-robot-data/robots/tiago2_description/meshes/arm_tiago_pro/arm_3_link.stl" scale="1 1 1"/>
      </geometry>
      <material name="pal/DarkGrey"/>
    </visual>
    <collision>
      <origin rpy="0 0 0" xyz="0 0 0"/>
      <geometry>
        <mesh filename="package://example-robot-data/robots/tiago2_description/meshes/arm_tiago_pro/arm_3_link_collision.stl" scale="1 1 1"/>
      </geometry>
    </collision>
  </link>
  <!-- ARM 3 JOINT -->
  <joint name="arm_right_3_joint" type="revolute">
    <origin rpy="3.1415 1.5707 0" xyz="-0.15 -0.02 0"/>
    <parent link="arm_right_2_link"/>
    <child link="arm_right_3_link"/>
    <axis xyz="0 0 1"/>
    <limit effort="26" lower="-2.6000169866959526" upper="2.6000169866959526" velocity="2.35"/>
    <dynamics damping="1.0" friction="1.0"/>
    <safety_controller k_position="20" k_velocity="20" soft_lower_limit="-2.5300169866959528" soft_upper_limit="2.5300169866959528"/>
  </joint>
  <!-- ARM 4 LINK -->
  <link name="arm_right_4_link">
    <inertial>
      <origin rpy="0 0 0" xyz="-0.11649 -0.017864 0.0053772"/>
      <mass value="0.99204"/>
      <inertia ixx="0.00077294" ixy="-0.00011001" ixz="-0.00016136" iyy="0.0014605" iyz="-1.3224E-05" izz="0.0015605"/>
    </inertial>
    <visual>
      <origin rpy="0 0 0" xyz="0 0 0"/>
      <geometry>
        <mesh filename="package://example-robot-data/robots/tiago2_description/meshes/arm_tiago_pro/arm_4_link.stl" scale="1 1 1"/>
      </geometry>
      <material name="pal/DarkGrey"/>
    </visual>
    <collision>
      <origin rpy="0 0 0" xyz="0 0 0"/>
      <geometry>
        <mesh filename="package://example-robot-data/robots/tiago2_description/meshes/arm_tiago_pro/arm_4_link_collision.stl" scale="1 1 1"/>
      </geometry>
    </collision>
  </link>
  <!-- ARM 4 JOINT -->
  <joint name="arm_right_4_joint" type="revolute">
    <origin rpy="0 1.5708 0" xyz="0 0.02 0.18"/>
    <parent link="arm_right_3_link"/>
    <child link="arm_right_4_link"/>
    <axis xyz="0 0 1"/>
    <limit effort="26" lower="-2.4399702942880728" upper="1.1000810275320259" velocity="2.35"/>
    <dynamics damping="1.0" friction="1.0"/>
    <safety_controller k_position="20" k_velocity="20" soft_lower_limit="-2.369970294288073" soft_upper_limit="1.0300810275320258"/>
  </joint>
  <!-- ARM 5 LINK -->
  <link name="arm_right_5_link">
    <inertial>
      <origin rpy="0 0 0" xyz="0.0004859 0.00014289 0.129"/>
      <mass value="0.52538"/>
      <inertia ixx="0.0019111" ixy="-1.4245E-08" ixz="3.8663E-05" iyy="0.0018565" iyz="1.1356E-06" izz="0.00046496"/>
    </inertial>
    <visual>
      <origin rpy="0 0 0" xyz="0 0 0"/>
      <geometry>
        <mesh filename="package://example-robot-data/robots/tiago2_description/meshes/arm_tiago_pro/arm_5_link.stl" scale="1 1 1"/>
      </geometry>
      <material name="pal/DarkGrey"/>
    </visual>
    <collision>
      <origin rpy="0 0 0" xyz="0 0 0"/>
      <geometry>
        <mesh filename="package://example-robot-data/robots/tiago2_description/meshes/arm_tiago_pro/arm_5_link_collision.stl" scale="1 1 1"/>
      </geometry>
    </collision>
  </link>
  <!-- ARM 5 JOINT -->
  <joint name="arm_right_5_joint" type="revolute">
    <origin rpy="0 -1.5708 0" xyz="-0.15 -0.02 0"/>
    <parent link="arm_right_4_link"/>
    <child link="arm_right_5_link"/>
    <axis xyz="0 0 1"/>
    <limit effort="26" lower="-2.6000169866959526" upper="2.6000169866959526" velocity="2.35"/>
    <dynamics damping="1.0" friction="1.0"/>
    <safety_controller k_position="20" k_velocity="20" soft_lower_limit="-2.5300169866959528" soft_upper_limit="2.5300169866959528"/>
  </joint>
  <!-- ARM 6 LINK -->
  <link name="arm_right_6_link">
    <inertial>
      <origin rpy="0 0 0" xyz="-0.086822 -7.7905E-06 0.0045258"/>
      <mass value="0.66725"/>
      <inertia ixx="0.00035696" ixy="1.6019E-07" ixz="-9.5191E-05" iyy="0.00073846" iyz="2.118E-08" izz="0.00075321"/>
    </inertial>
    <visual>
      <origin rpy="0 0 0" xyz="0 0 0"/>
      <geometry>
        <mesh filename="package://example-robot-data/robots/tiago2_description/meshes/arm_tiago_pro/arm_6_link.stl" scale="1 1 1"/>
      </geometry>
      <material name="pal/DarkGrey"/>
    </visual>
    <collision>
      <origin rpy="0 0 0" xyz="0 0 0"/>
      <geometry>
        <mesh filename="package://example-robot-data/robots/tiago2_description/meshes/arm_tiago_pro/arm_6_link_collision.stl" scale="1 1 1"/>
      </geometry>
    </collision>
  </link>
  <!-- ARM 6 JOINT -->
  <joint name="arm_right_6_joint" type="revolute">
    <origin rpy="0 1.5708 0" xyz="0 0 0.185"/>
    <parent link="arm_right_5_link"/>
    <child link="arm_right_6_link"/>
    <axis xyz="0 0 1"/>
    <limit effort="26" lower="-1.9999727898603024" upper="1.9999727898603024" velocity="2.35"/>
    <dynamics damping="1.0" friction="1.0"/>
    <safety_controller k_position="20" k_velocity="20" soft_lower_limit="-1.9299727898603023" soft_upper_limit="1.9299727898603023"/>
  </joint>
  <!-- ARM 7 LINK -->
  <link name="arm_right_7_link">
    <inertial>
      <origin rpy="0 0 0" xyz="-6.764E-18 -1.4549E-16 0.018549"/>
      <mass value="0.10189"/>
      <inertia ixx="5.1076E-05" ixy="-1.0899E-21" ixz="-5.93E-21" iyy="5.0882E-05" iyz="-8.5344E-21" izz="9.705E-05"/>
    </inertial>
    <visual>
      <origin rpy="0 0 0" xyz="0 0 0"/>
      <geometry>
        <mesh filename="package://example-robot-data/robots/tiago2_description/meshes/arm_tiago_pro/arm_7_link.stl" scale="1 1 1"/>
      </geometry>
      <material name="pal/DarkGrey"/>
    </visual>
    <collision>
      <origin rpy="0 0 0" xyz="0 0 0"/>
      <geometry>
        <mesh filename="package://example-robot-data/robots/tiago2_description/meshes/arm_tiago_pro/arm_7_link_collision.stl" scale="1 1 1"/>
      </geometry>
    </collision>
  </link>
  <!-- ARM 7 JOINT -->
  <joint name="arm_right_7_joint" type="revolute">
    <origin rpy="0 -1.5708 0" xyz="-0.1166 0 0"/>
    <parent link="arm_right_6_link"/>
    <child link="arm_right_7_link"/>
    <axis xyz="0 0 1"/>
    <limit effort="26" lower="-2.6000169866959526" upper="2.6000169866959526" velocity="2.35"/>
    <dynamics damping="1.0" friction="1.0"/>
    <safety_controller k_position="20" k_velocity="20" soft_lower_limit="-2.5300169866959528" soft_upper_limit="2.5300169866959528"/>
  </joint>
  <!--***********************-->
  <!--        TOOL           -->
  <!--***********************-->
  <link name="arm_right_tool_link">
    <inertial>
      <origin rpy="0 0 0" xyz="5.0493E-18 -4.4892E-17 -0.0068514"/>
      <mass value="0.10189"/>
      <inertia ixx="5.1076E-05" ixy="-1.0374E-21" ixz="-5.9164E-21" iyy="5.0882E-05" iyz="-8.5211E-21" izz="9.705E-05"/>
    </inertial>
    <visual>
      <origin rpy="0 1.5707963267948966 0" xyz="0.001 0 0"/>
      <geometry>
        <cylinder length="0.01" radius="0.032"/>
      </geometry>
      <material name="pal/DarkGrey"/>
    </visual>
    <collision>
      <origin rpy="0 1.5707963267948966 0" xyz="0.001 0 0"/>
      <geometry>
        <cylinder length="0.01" radius="0.032"/>
      </geometry>
    </collision>
  </link>
  <joint name="arm_right_tool_joint" type="fixed">
    <parent link="arm_right_7_link"/>
    <child link="arm_right_tool_link"/>
    <origin rpy="0 -1.5707963267948966 1.5707963267948966" xyz="0 0 0.0184"/>
  </joint>
  <gazebo reference="arm_right_1_link">
    <material>Gazebo/DarkGrey</material>
    <mu1>0.9</mu1>
    <mu2>0.9</mu2>
  </gazebo>
  <gazebo reference="arm_right_2_link">
    <material>Gazebo/DarkGrey</material>
    <mu1>0.9</mu1>
    <mu2>0.9</mu2>
  </gazebo>
  <gazebo reference="arm_right_3_link">
    <material>Gazebo/DarkGrey</material>
    <mu1>0.9</mu1>
    <mu2>0.9</mu2>
  </gazebo>
  <gazebo reference="arm_right_4_link">
    <material>Gazebo/DarkGrey</material>
    <mu1>0.9</mu1>
    <mu2>0.9</mu2>
  </gazebo>
  <gazebo reference="arm_right_5_link">
    <material>Gazebo/DarkGrey</material>
    <mu1>0.9</mu1>
    <mu2>0.9</mu2>
  </gazebo>
  <gazebo reference="arm_right_6_link">
    <material>Gazebo/DarkGrey</material>
    <mu1>0.9</mu1>
    <mu2>0.9</mu2>
  </gazebo>
  <gazebo reference="arm_right_7_link">
    <material>Gazebo/DarkGrey</material>
    <mu1>0.9</mu1>
    <mu2>0.9</mu2>
  </gazebo>
  <gazebo reference="arm_right_1_joint">
    <implicitSpringDamper>1</implicitSpringDamper>
  </gazebo>
  <gazebo reference="arm_right_2_joint">
    <implicitSpringDamper>1</implicitSpringDamper>
  </gazebo>
  <gazebo reference="arm_right_3_joint">
    <implicitSpringDamper>1</implicitSpringDamper>
  </gazebo>
  <gazebo reference="arm_right_4_joint">
    <implicitSpringDamper>1</implicitSpringDamper>
  </gazebo>
  <gazebo reference="arm_right_5_joint">
    <implicitSpringDamper>1</implicitSpringDamper>
  </gazebo>
  <gazebo reference="arm_right_6_joint">
    <implicitSpringDamper>1</implicitSpringDamper>
  </gazebo>
  <gazebo reference="arm_right_7_joint">
    <implicitSpringDamper>1</implicitSpringDamper>
    <provideFeedback>1</provideFeedback>
  </gazebo>
  <transmission name="arm_right_1_trans">
    <type>sea_transmissions/SeaSimpleTransmission</type>
    <actuator name="arm_right_1_motor">
      <mechanicalReduction>121.0</mechanicalReduction>
    </actuator>
    <joint name="arm_right_1_joint">
      <actuators_data_ns>/actuators_data/arm_right_1_motor</actuators_data_ns>
      <joint_offset_ns>/arm_right_1_motor/output_offset</joint_offset_ns>
      <hardwareInterface>hardware_interface/PositionJointInterface</hardwareInterface>
      <hardwareInterface>hardware_interface/VelocityJointInterface</hardwareInterface>
      <hardwareInterface>hardware_interface/EffortJointInterface</hardwareInterface>
      <hardwareInterface>hardware_interface/JointStateInterface</hardwareInterface>
    </joint>
  </transmission>
  <transmission name="arm_right_2_trans">
    <type>sea_transmissions/SeaSimpleTransmission</type>
    <actuator name="arm_right_2_motor">
      <mechanicalReduction>121.0</mechanicalReduction>
    </actuator>
    <joint name="arm_right_2_joint">
      <actuators_data_ns>/actuators_data/arm_right_2_motor</actuators_data_ns>
      <joint_offset_ns>/arm_right_2_motor/output_offset</joint_offset_ns>
      <hardwareInterface>hardware_interface/PositionJointInterface</hardwareInterface>
      <hardwareInterface>hardware_interface/VelocityJointInterface</hardwareInterface>
      <hardwareInterface>hardware_interface/EffortJointInterface</hardwareInterface>
      <hardwareInterface>hardware_interface/JointStateInterface</hardwareInterface>
    </joint>
  </transmission>
  <transmission name="arm_right_3_trans">
    <type>sea_transmissions/SeaSimpleTransmission</type>
    <actuator name="arm_right_3_motor">
      <mechanicalReduction>101.0</mechanicalReduction>
    </actuator>
    <joint name="arm_right_3_joint">
      <actuators_data_ns>/actuators_data/arm_right_3_motor</actuators_data_ns>
      <joint_offset_ns>/arm_right_3_motor/output_offset</joint_offset_ns>
      <hardwareInterface>hardware_interface/PositionJointInterface</hardwareInterface>
      <hardwareInterface>hardware_interface/VelocityJointInterface</hardwareInterface>
      <hardwareInterface>hardware_interface/EffortJointInterface</hardwareInterface>
      <hardwareInterface>hardware_interface/JointStateInterface</hardwareInterface>
    </joint>
  </transmission>
  <transmission name="arm_right_4_trans">
    <type>sea_transmissions/SeaSimpleTransmission</type>
    <actuator name="arm_right_4_motor">
      <mechanicalReduction>101.0</mechanicalReduction>
    </actuator>
    <joint name="arm_right_4_joint">
      <actuators_data_ns>/actuators_data/arm_right_4_motor</actuators_data_ns>
      <joint_offset_ns>/arm_right_4_motor/output_offset</joint_offset_ns>
      <hardwareInterface>hardware_interface/PositionJointInterface</hardwareInterface>
      <hardwareInterface>hardware_interface/VelocityJointInterface</hardwareInterface>
      <hardwareInterface>hardware_interface/EffortJointInterface</hardwareInterface>
      <hardwareInterface>hardware_interface/JointStateInterface</hardwareInterface>
    </joint>
  </transmission>
  <transmission name="arm_right_5_trans">
    <type>sea_transmissions/SeaSimpleTransmission</type>
    <actuator name="arm_right_5_motor">
      <mechanicalReduction>101.0</mechanicalReduction>
    </actuator>
    <joint name="arm_right_5_joint">
      <actuators_data_ns>/actuators_data/arm_right_5_motor</actuators_data_ns>
      <joint_offset_ns>/arm_right_5_motor/output_offset</joint_offset_ns>
      <hardwareInterface>hardware_interface/PositionJointInterface</hardwareInterface>
      <hardwareInterface>hardware_interface/VelocityJointInterface</hardwareInterface>
      <hardwareInterface>hardware_interface/EffortJointInterface</hardwareInterface>
      <hardwareInterface>hardware_interface/JointStateInterface</hardwareInterface>
    </joint>
  </transmission>
  <transmission name="arm_right_6_trans">
    <type>sea_transmissions/SeaSimpleTransmission</type>
    <actuator name="arm_right_6_motor">
      <mechanicalReduction>101.0</mechanicalReduction>
    </actuator>
    <joint name="arm_right_6_joint">
      <actuators_data_ns>/actuators_data/arm_right_6_motor</actuators_data_ns>
      <joint_offset_ns>/arm_right_6_motor/output_offset</joint_offset_ns>
      <hardwareInterface>hardware_interface/PositionJointInterface</hardwareInterface>
      <hardwareInterface>hardware_interface/VelocityJointInterface</hardwareInterface>
      <hardwareInterface>hardware_interface/EffortJointInterface</hardwareInterface>
      <hardwareInterface>hardware_interface/JointStateInterface</hardwareInterface>
    </joint>
  </transmission>
  <transmission name="arm_right_7_trans">
    <type>sea_transmissions/SeaSimpleTransmission</type>
    <actuator name="arm_right_7_motor">
      <mechanicalReduction>101.0</mechanicalReduction>
    </actuator>
    <joint name="arm_right_7_joint">
      <actuators_data_ns>/actuators_data/arm_right_7_motor</actuators_data_ns>
      <joint_offset_ns>/arm_right_7_motor/output_offset</joint_offset_ns>
      <hardwareInterface>hardware_interface/PositionJointInterface</hardwareInterface>
      <hardwareInterface>hardware_interface/VelocityJointInterface</hardwareInterface>
      <hardwareInterface>hardware_interface/EffortJointInterface</hardwareInterface>
      <hardwareInterface>hardware_interface/JointStateInterface</hardwareInterface>
    </joint>
  </transmission>
  <!--************************-->
  <!--        ft sensor       -->
  <!--************************-->
  <link name="wrist_right_ft_link">
    <inertial>
      <mass value="0.2657"/>
      <inertia ixx="2.9766E-04" ixy="1.87E-06" ixz="8.95E-06" iyy="3.095E-04" iyz="2.07E-06" izz="1.6632E-04"/>
    </inertial>
    <visual>
      <origin rpy="0.0 0.0 0.0" xyz="0.0 0.0 0.0"/>
      <geometry>
        <mesh filename="package://example-robot-data/robots/tiago2_description/meshes/sensors/rokubi_ft_sensor.stl"/>
      </geometry>
      <material name="">
        <color rgba="0.29804 0.29804 0.29804 1"/>
      </material>
    </visual>
    <collision>
      <origin rpy="0 0 0" xyz="0 0 -0.030"/>
      <geometry>
        <cylinder length="0.05" radius="0.035"/>
      </geometry>
    </collision>
    <collision>
      <origin rpy="0 0 0.4363323129985824" xyz="0.035 0.011 -0.035"/>
      <geometry>
        <box size="0.0395 0.0496 0.053"/>
      </geometry>
    </collision>
  </link>
  <gazebo reference="wrist_right_ft_link">
    <material>Gazebo/DarkGrey</material>
    <mu1>0.9</mu1>
    <mu2>0.9</mu2>
  </gazebo>
  <joint name="wrist_right_ft_joint" type="fixed">
    <parent link="arm_right_tool_link"/>
    <child link="wrist_right_ft_link"/>
    <origin rpy="-1.5707963267948966 0.7853981633974483 -1.5707963267948966" xyz="0.045 0 0"/>
  </joint>
  <!--***********************-->
  <!--       FT TOOL         -->
  <!--***********************-->
  <link name="wrist_right_ft_tool_link">
    <inertial>
      <mass value="0.1"/>
      <inertia ixx="1.64E-05" ixy="0.0" ixz="0.0" iyy="1.64E-05" iyz="0.0" izz="3.125E-05"/>
    </inertial>
    <visual>
      <origin rpy="0 1.5707963267948966 0" xyz="0.001 0 0"/>
      <geometry>
        <cylinder length="0.01" radius="0.032"/>
      </geometry>
      <material name="pal/DarkGrey"/>
    </visual>
    <collision>
      <origin rpy="0 1.5707963267948966 0" xyz="0.001 0 0"/>
      <geometry>
        <cylinder length="0.01" radius="0.032"/>
      </geometry>
    </collision>
  </link>
  <joint name="wrist_right_ft_tool_joint" type="fixed">
    <parent link="wrist_right_ft_link"/>
    <child link="wrist_right_ft_tool_link"/>
    <origin rpy="0.7853981633974483 -1.5707963267948966 0.0" xyz="0 0 0.005"/>
  </joint>
  <!--************************-->
  <!--        ft sensor       -->
  <!--************************-->
  <link name="wrist_left_ft_link">
    <inertial>
      <mass value="0.2657"/>
      <inertia ixx="2.9766E-04" ixy="1.87E-06" ixz="8.95E-06" iyy="3.095E-04" iyz="2.07E-06" izz="1.6632E-04"/>
    </inertial>
    <visual>
      <origin rpy="0.0 0.0 0.0" xyz="0.0 0.0 0.0"/>
      <geometry>
        <mesh filename="package://example-robot-data/robots/tiago2_description/meshes/sensors/rokubi_ft_sensor.stl"/>
      </geometry>
      <material name="">
        <color rgba="0.29804 0.29804 0.29804 1"/>
      </material>
    </visual>
    <collision>
      <origin rpy="0 0 0" xyz="0 0 -0.030"/>
      <geometry>
        <cylinder length="0.05" radius="0.035"/>
      </geometry>
    </collision>
    <collision>
      <origin rpy="0 0 0.4363323129985824" xyz="0.035 0.011 -0.035"/>
      <geometry>
        <box size="0.0395 0.0496 0.053"/>
      </geometry>
    </collision>
  </link>
  <gazebo reference="wrist_left_ft_link">
    <material>Gazebo/DarkGrey</material>
    <mu1>0.9</mu1>
    <mu2>0.9</mu2>
  </gazebo>
  <joint name="wrist_left_ft_joint" type="fixed">
    <parent link="arm_left_tool_link"/>
    <child link="wrist_left_ft_link"/>
    <origin rpy="-1.5707963267948966 0.7853981633974483 -1.5707963267948966" xyz="0.045 0 0"/>
  </joint>
  <!--***********************-->
  <!--       FT TOOL         -->
  <!--***********************-->
  <link name="wrist_left_ft_tool_link">
    <inertial>
      <mass value="0.1"/>
      <inertia ixx="1.64E-05" ixy="0.0" ixz="0.0" iyy="1.64E-05" iyz="0.0" izz="3.125E-05"/>
    </inertial>
    <visual>
      <origin rpy="0 1.5707963267948966 0" xyz="0.001 0 0"/>
      <geometry>
        <cylinder length="0.01" radius="0.032"/>
      </geometry>
      <material name="pal/DarkGrey"/>
    </visual>
    <collision>
      <origin rpy="0 1.5707963267948966 0" xyz="0.001 0 0"/>
      <geometry>
        <cylinder length="0.01" radius="0.032"/>
      </geometry>
    </collision>
  </link>
  <joint name="wrist_left_ft_tool_joint" type="fixed">
    <parent link="wrist_left_ft_link"/>
    <child link="wrist_left_ft_tool_link"/>
    <origin rpy="0.7853981633974483 -1.5707963267948966 0.0" xyz="0 0 0.005"/>
  </joint>
  <!-- <xacro:include filename="$(find pal_pro_gripper_description)/urdf/grasping_frames.xacro" /> -->
  <link name="gripper_left_base_link">
    <inertial>
      <origin rpy="0 0 0" xyz="6.0291E-05 -0.00013653 -0.0051371"/>
      <mass value="0.64278"/>
      <inertia ixx="0.00033701" ixy="-8.3235E-07" ixz="5.4122E-07" iyy="0.00042750" iyz="-4.3734E-07" izz="0.00048564"/>
    </inertial>
    <visual>
      <origin rpy="0 0 0" xyz="0 0 0"/>
      <geometry>
        <mesh filename="package://example-robot-data/robots/tiago2_description/meshes/pal_pro_gripper/base_link.stl"/>
      </geometry>
      <material name="pal/DarkGrey"/>
    </visual>
    <collision>
      <origin rpy="0 0 0" xyz="0 0 0"/>
      <geometry>
        <mesh filename="package://example-robot-data/robots/tiago2_description/meshes/pal_pro_gripper/base_link.stl"/>
      </geometry>
    </collision>
  </link>
  <joint name="gripper_left_base_joint" type="fixed">
    <origin rpy="0 1.5707963267948966 0" xyz="0.052 0.0 0.0"/>
    <parent link="wrist_left_ft_tool_link"/>
    <child link="gripper_left_base_link"/>
    <axis xyz="0 0 0"/>
  </joint>
  <gazebo reference="gripper_left_inner_finger_left_link">
    <material>Gazebo/White</material>
    <mu1>0.9</mu1>
    <mu2>0.9</mu2>
  </gazebo>
  <gazebo reference="gripper_left_inner_finger_right_link">
    <material>Gazebo/White</material>
    <mu1>0.9</mu1>
    <mu2>0.9</mu2>
  </gazebo>
  <gazebo reference="gripper_left_outer_finger_left_link">
    <material>Gazebo/White</material>
    <mu1>0.9</mu1>
    <mu2>0.9</mu2>
  </gazebo>
  <gazebo reference="gripper_left_outer_finger_right_link">
    <material>Gazebo/White</material>
    <mu1>0.9</mu1>
    <mu2>0.9</mu2>
  </gazebo>
  <gazebo reference="gripper_left_fingertip_right_link">
    <material>Gazebo/White</material>
    <mu1>0.9</mu1>
    <mu2>0.9</mu2>
  </gazebo>
  <gazebo reference="gripper_left_fingertip_left_link">
    <material>Gazebo/White</material>
    <mu1>0.9</mu1>
    <mu2>0.9</mu2>
  </gazebo>
  <gazebo reference="gripper_left_base_link">
    <material>Gazebo/DarkGrey</material>
    <mu1>0.9</mu1>
    <mu2>0.9</mu2>
  </gazebo>
  <gazebo reference="gripper_left_finger_joint">
    <implicitSpringDamper>1</implicitSpringDamper>
    <provideFeedback>1</provideFeedback>
  </gazebo>
  <link name="gripper_left_inner_finger_left_link">
    <inertial>
      <origin rpy="0 0 0" xyz="-1.7347E-18 0.024759 0"/>
      <mass value="0.018619"/>
      <inertia ixx="4.8806E-06" ixy="-7.6762E-22" ixz="1.0244E-22" iyy="2.5471E-07" iyz="-1.1841E-21" izz="4.9573E-06"/>
    </inertial>
    <visual>
      <origin rpy="0 0 0" xyz="0 0 0"/>
      <geometry>
        <mesh filename="package://example-robot-data/robots/tiago2_description/meshes/pal_pro_gripper/inner_finger.stl"/>
      </geometry>
      <material name="White"/>
    </visual>
    <collision>
      <origin rpy="0 0 0" xyz="0 0 0"/>
      <geometry>
        <mesh filename="package://example-robot-data/robots/tiago2_description/meshes/pal_pro_gripper/inner_finger.stl"/>
      </geometry>
    </collision>
  </link>
  <joint name="gripper_left_inner_finger_left_joint" type="revolute">
    <origin rpy="-1.5707963267948966 2.303834612632515 0" xyz="-0.013977 0 0.033032"/>
    <parent link="gripper_left_base_link"/>
    <child link="gripper_left_inner_finger_left_link"/>
    <axis xyz="0 0 1"/>
    <limit effort="0.1" lower="0" upper="0.9250245035569946" velocity="2"/>
    <mimic joint="gripper_left_finger_joint" multiplier="1" offset="0"/>
  </joint>
  <gazebo>
    <plugin filename="libroboticsgroup_upatras_gazebo_mimic_joint_plugin.so" name="gripper_left_left_mimic_pro_gripper_1_mimic_joint_plugin">
      <joint>gripper_left_finger_joint</joint>
      <mimicJoint>gripper_left_inner_finger_left_joint</mimicJoint>
      <multiplier>1.0</multiplier>
      <offset>0</offset>
      <sensitiveness>0.0</sensitiveness>
      <!-- if absolute difference between setpoint and process value is below this threshold, do nothing; 0.0 = disable [rad] -->
      <maxEffort>0.1</maxEffort>
    </plugin>
  </gazebo>
  <link name="gripper_left_outer_finger_left_link">
    <inertial>
      <origin rpy="0 0 0" xyz="-0.001283 0.014397 0"/>
      <mass value="0.015989"/>
      <inertia ixx="5.9879E-06" ixy="-5.2173E-07" ixz="5.9144E-23" iyy="4.8725E-07" iyz="7.3911E-23" izz="6.1497E-06"/>
    </inertial>
    <visual>
      <origin rpy="0 0 0" xyz="0 0 0"/>
      <geometry>
        <mesh filename="package://example-robot-data/robots/tiago2_description/meshes/pal_pro_gripper/outer_finger.stl"/>
      </geometry>
      <material name="White"/>
    </visual>
    <collision>
      <origin rpy="0 0 0" xyz="0 0 0"/>
      <geometry>
        <mesh filename="package://example-robot-data/robots/tiago2_description/meshes/pal_pro_gripper/outer_finger.stl"/>
      </geometry>
    </collision>
  </link>
  <joint name="gripper_left_finger_joint" type="revolute">
    <origin rpy="-1.5707963267948966 2.303834612632515 0" xyz="-0.0288  0.00 0.0285"/>
    <parent link="gripper_left_base_link"/>
    <child link="gripper_left_outer_finger_left_link"/>
    <axis xyz="0 0 1"/>
    <limit effort="0.1" lower="0" upper="0.9250245035569946" velocity="2"/>
    <dynamics damping="0.03"/>
  </joint>
  <link name="gripper_left_fingertip_left_link">
    <inertial>
      <origin rpy="0 0 0" xyz="-6.9960E-04 0.01167 0.0"/>
      <mass value="0.03266"/>
      <inertia ixx="3.6361E-06" ixy="3.4071E-07" ixz="-1.4191E-14" iyy="1.7070E-06" iyz="-3.3433E-14" izz="2.8395E-06"/>
    </inertial>
    <visual>
      <origin rpy="0 0 0" xyz="0 0 0"/>
      <geometry>
        <mesh filename="package://example-robot-data/robots/tiago2_description/meshes/pal_pro_gripper/fingertip.stl"/>
      </geometry>
      <material name="White"/>
    </visual>
    <collision>
      <origin rpy="0 0 0" xyz="0 0 0"/>
      <geometry>
        <mesh filename="package://example-robot-data/robots/tiago2_description/meshes/pal_pro_gripper/fingertip.stl"/>
      </geometry>
    </collision>
  </link>
  <joint name="gripper_left_fingertip_left_joint" type="revolute">
    <origin rpy="0 0 0.8377580409572782" xyz="0 0.05 0.000"/>
    <parent link="gripper_left_inner_finger_left_link"/>
    <child link="gripper_left_fingertip_left_link"/>
    <axis xyz="0 0 1"/>
    <limit effort="0.1" lower="-0.9250245035569946" upper="0" velocity="2"/>
    <mimic joint="gripper_left_finger_joint" multiplier="-1" offset="0"/>
  </joint>
  <gazebo>
    <plugin filename="libroboticsgroup_upatras_gazebo_mimic_joint_plugin.so" name="gripper_left_left_mimic_pro_gripper_3_mimic_joint_plugin">
      <joint>gripper_left_finger_joint</joint>
      <mimicJoint>gripper_left_fingertip_left_joint</mimicJoint>
      <multiplier>-1.0</multiplier>
      <offset>0.0</offset>
      <sensitiveness>0.0</sensitiveness>
      <!-- if absolute difference between setpoint and process value is below this threshold, do nothing; 0.0 = disable [rad] -->
      <maxEffort>0.1</maxEffort>
    </plugin>
  </gazebo>
  <link name="gripper_left_inner_finger_right_link">
    <inertial>
      <origin rpy="0 0 0" xyz="-1.7347E-18 0.024759 0"/>
      <mass value="0.018619"/>
      <inertia ixx="4.8806E-06" ixy="-7.6762E-22" ixz="1.0244E-22" iyy="2.5471E-07" iyz="-1.1841E-21" izz="4.9573E-06"/>
    </inertial>
    <visual>
      <origin rpy="0 0 0" xyz="0 0 0"/>
      <geometry>
        <mesh filename="package://example-robot-data/robots/tiago2_description/meshes/pal_pro_gripper/inner_finger.stl"/>
      </geometry>
      <material name="White"/>
    </visual>
    <collision>
      <origin rpy="0 0 0" xyz="0 0 0"/>
      <geometry>
        <mesh filename="package://example-robot-data/robots/tiago2_description/meshes/pal_pro_gripper/inner_finger.stl"/>
      </geometry>
    </collision>
  </link>
  <joint name="gripper_left_inner_finger_right_joint" type="revolute">
    <origin rpy="1.5707963267948966 0.8377580409572782 0" xyz="0.013977 0 0.033032"/>
    <parent link="gripper_left_base_link"/>
    <child link="gripper_left_inner_finger_right_link"/>
    <axis xyz="0 0 1"/>
    <limit effort="0.1" lower="0" upper="0.9250245035569946" velocity="2"/>
    <mimic joint="gripper_left_finger_joint" multiplier="1" offset="0"/>
  </joint>
  <gazebo>
    <plugin filename="libroboticsgroup_upatras_gazebo_mimic_joint_plugin.so" name="gripper_left_right_mimic_pro_gripper_1_mimic_joint_plugin">
      <joint>gripper_left_finger_joint</joint>
      <mimicJoint>gripper_left_inner_finger_right_joint</mimicJoint>
      <multiplier>1.0</multiplier>
      <offset>0</offset>
      <sensitiveness>0.0</sensitiveness>
      <!-- if absolute difference between setpoint and process value is below this threshold, do nothing; 0.0 = disable [rad] -->
      <maxEffort>0.1</maxEffort>
    </plugin>
  </gazebo>
  <link name="gripper_left_outer_finger_right_link">
    <inertial>
      <origin rpy="0 0 0" xyz="-0.001283 0.014397 0"/>
      <mass value="0.015989"/>
      <inertia ixx="5.9879E-06" ixy="-5.2173E-07" ixz="5.9144E-23" iyy="4.8725E-07" iyz="7.3911E-23" izz="6.1497E-06"/>
    </inertial>
    <visual>
      <origin rpy="0 0 0" xyz="0 0 0"/>
      <geometry>
        <mesh filename="package://example-robot-data/robots/tiago2_description/meshes/pal_pro_gripper/outer_finger.stl"/>
      </geometry>
      <material name="White"/>
    </visual>
    <collision>
      <origin rpy="0 0 0" xyz="0 0 0"/>
      <geometry>
        <mesh filename="package://example-robot-data/robots/tiago2_description/meshes/pal_pro_gripper/outer_finger.stl"/>
      </geometry>
    </collision>
  </link>
  <joint name="gripper_left_outer_finger_right_joint" type="revolute">
    <origin rpy="1.5707963267948966 0.8377580409572782 0" xyz="0.0288  0.00 0.0285"/>
    <parent link="gripper_left_base_link"/>
    <child link="gripper_left_outer_finger_right_link"/>
    <axis xyz="0 0 1"/>
    <limit effort="0.1" lower="0" upper="0.9250245035569946" velocity="2"/>
    <mimic joint="gripper_left_finger_joint" multiplier="1" offset="0"/>
  </joint>
  <gazebo>
    <plugin filename="libroboticsgroup_upatras_gazebo_mimic_joint_plugin.so" name="gripper_left_right_mimic_pro_gripper_2_mimic_joint_plugin">
      <joint>gripper_left_finger_joint</joint>
      <mimicJoint>gripper_left_outer_finger_right_joint</mimicJoint>
      <multiplier>1.0</multiplier>
      <offset>0.0</offset>
      <sensitiveness>0.0</sensitiveness>
      <!-- if absolute difference between setpoint and process value is below this threshold, do nothing; 0.0 = disable [rad] -->
      <maxEffort>0.1</maxEffort>
    </plugin>
  </gazebo>
  <link name="gripper_left_fingertip_right_link">
    <inertial>
      <origin rpy="0 0 0" xyz="-6.9960E-04 0.01167 0.0"/>
      <mass value="0.03266"/>
      <inertia ixx="3.6361E-06" ixy="3.4071E-07" ixz="-1.4191E-14" iyy="1.7070E-06" iyz="-3.3433E-14" izz="2.8395E-06"/>
    </inertial>
    <visual>
      <origin rpy="0 0 0" xyz="0 0 0"/>
      <geometry>
        <mesh filename="package://example-robot-data/robots/tiago2_description/meshes/pal_pro_gripper/fingertip.stl"/>
      </geometry>
      <material name="White"/>
    </visual>
    <collision>
      <origin rpy="0 0 0" xyz="0 0 0"/>
      <geometry>
        <mesh filename="package://example-robot-data/robots/tiago2_description/meshes/pal_pro_gripper/fingertip.stl"/>
      </geometry>
    </collision>
  </link>
  <joint name="gripper_left_fingertip_right_joint" type="revolute">
    <origin rpy="0 0 0.8377580409572782" xyz="0 0.05 0.000"/>
    <parent link="gripper_left_inner_finger_right_link"/>
    <child link="gripper_left_fingertip_right_link"/>
    <axis xyz="0 0 1"/>
    <limit effort="0.1" lower="-0.9250245035569946" upper="0" velocity="2"/>
    <mimic joint="gripper_left_finger_joint" multiplier="-1" offset="0"/>
  </joint>
  <gazebo>
    <plugin filename="libroboticsgroup_upatras_gazebo_mimic_joint_plugin.so" name="gripper_left_right_mimic_pro_gripper_3_mimic_joint_plugin">
      <joint>gripper_left_finger_joint</joint>
      <mimicJoint>gripper_left_fingertip_right_joint</mimicJoint>
      <multiplier>-1.0</multiplier>
      <offset>0.0</offset>
      <sensitiveness>0.0</sensitiveness>
      <!-- if absolute difference between setpoint and process value is below this threshold, do nothing; 0.0 = disable [rad] -->
      <maxEffort>0.1</maxEffort>
    </plugin>
  </gazebo>
  <transmission name="gripper_left_finger_trans">
    <type>transmission_interface/SimpleTransmission</type>
    <joint name="gripper_left_finger_joint">
      <hardwareInterface>hardware_interface/PositionJointInterface</hardwareInterface>
      <hardwareInterface>hardware_interface/JointStateInterface</hardwareInterface>
    </joint>
    <actuator name="gripper_left_motor">
      <mechanicalReduction>1</mechanicalReduction>
      <hardwareInterface>hardware_interface/PositionJointInterface</hardwareInterface>
      <hardwareInterface>hardware_interface/JointStateInterface</hardwareInterface>
    </actuator>
  </transmission>
  <gazebo>
    <gripper name="gripper_left_grasp">
      <grasp_check>
        <attach_steps>3</attach_steps>
        <detach_steps>1</detach_steps>
        <!-- should not change otherwise the object will be attached to the gripper too much time -->
        <min_contact_count>3</min_contact_count>
      </grasp_check>
      <gripper_link>gripper_left_outer_finger_left_link</gripper_link>
      <gripper_link>gripper_left_outer_finger_right_link</gripper_link>
      <palm_link>wrist_left_ft_tool_link</palm_link>
    </gripper>
  </gazebo>
  <!-- <xacro:include filename="$(find pal_pro_gripper_description)/urdf/grasping_frames.xacro" /> -->
  <link name="gripper_right_base_link">
    <inertial>
      <origin rpy="0 0 0" xyz="6.0291E-05 -0.00013653 -0.0051371"/>
      <mass value="0.64278"/>
      <inertia ixx="0.00033701" ixy="-8.3235E-07" ixz="5.4122E-07" iyy="0.00042750" iyz="-4.3734E-07" izz="0.00048564"/>
    </inertial>
    <visual>
      <origin rpy="0 0 0" xyz="0 0 0"/>
      <geometry>
        <mesh filename="package://example-robot-data/robots/tiago2_description/meshes/pal_pro_gripper/base_link.stl"/>
      </geometry>
      <material name="pal/DarkGrey"/>
    </visual>
    <collision>
      <origin rpy="0 0 0" xyz="0 0 0"/>
      <geometry>
        <mesh filename="package://example-robot-data/robots/tiago2_description/meshes/pal_pro_gripper/base_link.stl"/>
      </geometry>
    </collision>
  </link>
  <joint name="gripper_right_base_joint" type="fixed">
    <origin rpy="0 1.5707963267948966 0" xyz="0.052 0.0 0.0"/>
    <parent link="wrist_right_ft_tool_link"/>
    <child link="gripper_right_base_link"/>
    <axis xyz="0 0 0"/>
  </joint>
  <gazebo reference="gripper_right_inner_finger_left_link">
    <material>Gazebo/White</material>
    <mu1>0.9</mu1>
    <mu2>0.9</mu2>
  </gazebo>
  <gazebo reference="gripper_right_inner_finger_right_link">
    <material>Gazebo/White</material>
    <mu1>0.9</mu1>
    <mu2>0.9</mu2>
  </gazebo>
  <gazebo reference="gripper_right_outer_finger_left_link">
    <material>Gazebo/White</material>
    <mu1>0.9</mu1>
    <mu2>0.9</mu2>
  </gazebo>
  <gazebo reference="gripper_right_outer_finger_right_link">
    <material>Gazebo/White</material>
    <mu1>0.9</mu1>
    <mu2>0.9</mu2>
  </gazebo>
  <gazebo reference="gripper_right_fingertip_right_link">
    <material>Gazebo/White</material>
    <mu1>0.9</mu1>
    <mu2>0.9</mu2>
  </gazebo>
  <gazebo reference="gripper_right_fingertip_left_link">
    <material>Gazebo/White</material>
    <mu1>0.9</mu1>
    <mu2>0.9</mu2>
  </gazebo>
  <gazebo reference="gripper_right_base_link">
    <material>Gazebo/DarkGrey</material>
    <mu1>0.9</mu1>
    <mu2>0.9</mu2>
  </gazebo>
  <gazebo reference="gripper_right_finger_joint">
    <implicitSpringDamper>1</implicitSpringDamper>
    <provideFeedback>1</provideFeedback>
  </gazebo>
  <link name="gripper_right_inner_finger_left_link">
    <inertial>
      <origin rpy="0 0 0" xyz="-1.7347E-18 0.024759 0"/>
      <mass value="0.018619"/>
      <inertia ixx="4.8806E-06" ixy="-7.6762E-22" ixz="1.0244E-22" iyy="2.5471E-07" iyz="-1.1841E-21" izz="4.9573E-06"/>
    </inertial>
    <visual>
      <origin rpy="0 0 0" xyz="0 0 0"/>
      <geometry>
        <mesh filename="package://example-robot-data/robots/tiago2_description/meshes/pal_pro_gripper/inner_finger.stl"/>
      </geometry>
      <material name="White"/>
    </visual>
    <collision>
      <origin rpy="0 0 0" xyz="0 0 0"/>
      <geometry>
        <mesh filename="package://example-robot-data/robots/tiago2_description/meshes/pal_pro_gripper/inner_finger.stl"/>
      </geometry>
    </collision>
  </link>
  <joint name="gripper_right_inner_finger_left_joint" type="revolute">
    <origin rpy="-1.5707963267948966 2.303834612632515 0" xyz="-0.013977 0 0.033032"/>
    <parent link="gripper_right_base_link"/>
    <child link="gripper_right_inner_finger_left_link"/>
    <axis xyz="0 0 1"/>
    <limit effort="0.1" lower="0" upper="0.9250245035569946" velocity="2"/>
    <mimic joint="gripper_right_finger_joint" multiplier="1" offset="0"/>
  </joint>
  <gazebo>
    <plugin filename="libroboticsgroup_upatras_gazebo_mimic_joint_plugin.so" name="gripper_right_left_mimic_pro_gripper_1_mimic_joint_plugin">
      <joint>gripper_right_finger_joint</joint>
      <mimicJoint>gripper_right_inner_finger_left_joint</mimicJoint>
      <multiplier>1.0</multiplier>
      <offset>0</offset>
      <sensitiveness>0.0</sensitiveness>
      <!-- if absolute difference between setpoint and process value is below this threshold, do nothing; 0.0 = disable [rad] -->
      <maxEffort>0.1</maxEffort>
    </plugin>
  </gazebo>
  <link name="gripper_right_outer_finger_left_link">
    <inertial>
      <origin rpy="0 0 0" xyz="-0.001283 0.014397 0"/>
      <mass value="0.015989"/>
      <inertia ixx="5.9879E-06" ixy="-5.2173E-07" ixz="5.9144E-23" iyy="4.8725E-07" iyz="7.3911E-23" izz="6.1497E-06"/>
    </inertial>
    <visual>
      <origin rpy="0 0 0" xyz="0 0 0"/>
      <geometry>
        <mesh filename="package://example-robot-data/robots/tiago2_description/meshes/pal_pro_gripper/outer_finger.stl"/>
      </geometry>
      <material name="White"/>
    </visual>
    <collision>
      <origin rpy="0 0 0" xyz="0 0 0"/>
      <geometry>
        <mesh filename="package://example-robot-data/robots/tiago2_description/meshes/pal_pro_gripper/outer_finger.stl"/>
      </geometry>
    </collision>
  </link>
  <joint name="gripper_right_finger_joint" type="revolute">
    <origin rpy="-1.5707963267948966 2.303834612632515 0" xyz="-0.0288  0.00 0.0285"/>
    <parent link="gripper_right_base_link"/>
    <child link="gripper_right_outer_finger_left_link"/>
    <axis xyz="0 0 1"/>
    <limit effort="0.1" lower="0" upper="0.9250245035569946" velocity="2"/>
    <dynamics damping="0.03"/>
  </joint>
  <link name="gripper_right_fingertip_left_link">
    <inertial>
      <origin rpy="0 0 0" xyz="-6.9960E-04 0.01167 0.0"/>
      <mass value="0.03266"/>
      <inertia ixx="3.6361E-06" ixy="3.4071E-07" ixz="-1.4191E-14" iyy="1.7070E-06" iyz="-3.3433E-14" izz="2.8395E-06"/>
    </inertial>
    <visual>
      <origin rpy="0 0 0" xyz="0 0 0"/>
      <geometry>
        <mesh filename="package://example-robot-data/robots/tiago2_description/meshes/pal_pro_gripper/fingertip.stl"/>
      </geometry>
      <material name="White"/>
    </visual>
    <collision>
      <origin rpy="0 0 0" xyz="0 0 0"/>
      <geometry>
        <mesh filename="package://example-robot-data/robots/tiago2_description/meshes/pal_pro_gripper/fingertip.stl"/>
      </geometry>
    </collision>
  </link>
  <joint name="gripper_right_fingertip_left_joint" type="revolute">
    <origin rpy="0 0 0.8377580409572782" xyz="0 0.05 0.000"/>
    <parent link="gripper_right_inner_finger_left_link"/>
    <child link="gripper_right_fingertip_left_link"/>
    <axis xyz="0 0 1"/>
    <limit effort="0.1" lower="-0.9250245035569946" upper="0" velocity="2"/>
    <mimic joint="gripper_right_finger_joint" multiplier="-1" offset="0"/>
  </joint>
  <gazebo>
    <plugin filename="libroboticsgroup_upatras_gazebo_mimic_joint_plugin.so" name="gripper_right_left_mimic_pro_gripper_3_mimic_joint_plugin">
      <joint>gripper_right_finger_joint</joint>
      <mimicJoint>gripper_right_fingertip_left_joint</mimicJoint>
      <multiplier>-1.0</multiplier>
      <offset>0.0</offset>
      <sensitiveness>0.0</sensitiveness>
      <!-- if absolute difference between setpoint and process value is below this threshold, do nothing; 0.0 = disable [rad] -->
      <maxEffort>0.1</maxEffort>
    </plugin>
  </gazebo>
  <link name="gripper_right_inner_finger_right_link">
    <inertial>
      <origin rpy="0 0 0" xyz="-1.7347E-18 0.024759 0"/>
      <mass value="0.018619"/>
      <inertia ixx="4.8806E-06" ixy="-7.6762E-22" ixz="1.0244E-22" iyy="2.5471E-07" iyz="-1.1841E-21" izz="4.9573E-06"/>
    </inertial>
    <visual>
      <origin rpy="0 0 0" xyz="0 0 0"/>
      <geometry>
        <mesh filename="package://example-robot-data/robots/tiago2_description/meshes/pal_pro_gripper/inner_finger.stl"/>
      </geometry>
      <material name="White"/>
    </visual>
    <collision>
      <origin rpy="0 0 0" xyz="0 0 0"/>
      <geometry>
        <mesh filename="package://example-robot-data/robots/tiago2_description/meshes/pal_pro_gripper/inner_finger.stl"/>
      </geometry>
    </collision>
  </link>
  <joint name="gripper_right_inner_finger_right_joint" type="revolute">
    <origin rpy="1.5707963267948966 0.8377580409572782 0" xyz="0.013977 0 0.033032"/>
    <parent link="gripper_right_base_link"/>
    <child link="gripper_right_inner_finger_right_link"/>
    <axis xyz="0 0 1"/>
    <limit effort="0.1" lower="0" upper="0.9250245035569946" velocity="2"/>
    <mimic joint="gripper_right_finger_joint" multiplier="1" offset="0"/>
  </joint>
  <gazebo>
    <plugin filename="libroboticsgroup_upatras_gazebo_mimic_joint_plugin.so" name="gripper_right_right_mimic_pro_gripper_1_mimic_joint_plugin">
      <joint>gripper_right_finger_joint</joint>
      <mimicJoint>gripper_right_inner_finger_right_joint</mimicJoint>
      <multiplier>1.0</multiplier>
      <offset>0</offset>
      <sensitiveness>0.0</sensitiveness>
      <!-- if absolute difference between setpoint and process value is below this threshold, do nothing; 0.0 = disable [rad] -->
      <maxEffort>0.1</maxEffort>
    </plugin>
  </gazebo>
  <link name="gripper_right_outer_finger_right_link">
    <inertial>
      <origin rpy="0 0 0" xyz="-0.001283 0.014397 0"/>
      <mass value="0.015989"/>
      <inertia ixx="5.9879E-06" ixy="-5.2173E-07" ixz="5.9144E-23" iyy="4.8725E-07" iyz="7.3911E-23" izz="6.1497E-06"/>
    </inertial>
    <visual>
      <origin rpy="0 0 0" xyz="0 0 0"/>
      <geometry>
        <mesh filename="package://example-robot-data/robots/tiago2_description/meshes/pal_pro_gripper/outer_finger.stl"/>
      </geometry>
      <material name="White"/>
    </visual>
    <collision>
      <origin rpy="0 0 0" xyz="0 0 0"/>
      <geometry>
        <mesh filename="package://example-robot-data/robots/tiago2_description/meshes/pal_pro_gripper/outer_finger.stl"/>
      </geometry>
    </collision>
  </link>
  <joint name="gripper_right_outer_finger_right_joint" type="revolute">
    <origin rpy="1.5707963267948966 0.8377580409572782 0" xyz="0.0288  0.00 0.0285"/>
    <parent link="gripper_right_base_link"/>
    <child link="gripper_right_outer_finger_right_link"/>
    <axis xyz="0 0 1"/>
    <limit effort="0.1" lower="0" upper="0.9250245035569946" velocity="2"/>
    <mimic joint="gripper_right_finger_joint" multiplier="1" offset="0"/>
  </joint>
  <gazebo>
    <plugin filename="libroboticsgroup_upatras_gazebo_mimic_joint_plugin.so" name="gripper_right_right_mimic_pro_gripper_2_mimic_joint_plugin">
      <joint>gripper_right_finger_joint</joint>
      <mimicJoint>gripper_right_outer_finger_right_joint</mimicJoint>
      <multiplier>1.0</multiplier>
      <offset>0.0</offset>
      <sensitiveness>0.0</sensitiveness>
      <!-- if absolute difference between setpoint and process value is below this threshold, do nothing; 0.0 = disable [rad] -->
      <maxEffort>0.1</maxEffort>
    </plugin>
  </gazebo>
  <link name="gripper_right_fingertip_right_link">
    <inertial>
      <origin rpy="0 0 0" xyz="-6.9960E-04 0.01167 0.0"/>
      <mass value="0.03266"/>
      <inertia ixx="3.6361E-06" ixy="3.4071E-07" ixz="-1.4191E-14" iyy="1.7070E-06" iyz="-3.3433E-14" izz="2.8395E-06"/>
    </inertial>
    <visual>
      <origin rpy="0 0 0" xyz="0 0 0"/>
      <geometry>
        <mesh filename="package://example-robot-data/robots/tiago2_description/meshes/pal_pro_gripper/fingertip.stl"/>
      </geometry>
      <material name="White"/>
    </visual>
    <collision>
      <origin rpy="0 0 0" xyz="0 0 0"/>
      <geometry>
        <mesh filename="package://example-robot-data/robots/tiago2_description/meshes/pal_pro_gripper/fingertip.stl"/>
      </geometry>
    </collision>
  </link>
  <joint name="gripper_right_fingertip_right_joint" type="revolute">
    <origin rpy="0 0 0.8377580409572782" xyz="0 0.05 0.000"/>
    <parent link="gripper_right_inner_finger_right_link"/>
    <child link="gripper_right_fingertip_right_link"/>
    <axis xyz="0 0 1"/>
    <limit effort="0.1" lower="-0.9250245035569946" upper="0" velocity="2"/>
    <mimic joint="gripper_right_finger_joint" multiplier="-1" offset="0"/>
  </joint>
  <gazebo>
    <plugin filename="libroboticsgroup_upatras_gazebo_mimic_joint_plugin.so" name="gripper_right_right_mimic_pro_gripper_3_mimic_joint_plugin">
      <joint>gripper_right_finger_joint</joint>
      <mimicJoint>gripper_right_fingertip_right_joint</mimicJoint>
      <multiplier>-1.0</multiplier>
      <offset>0.0</offset>
      <sensitiveness>0.0</sensitiveness>
      <!-- if absolute difference between setpoint and process value is below this threshold, do nothing; 0.0 = disable [rad] -->
      <maxEffort>0.1</maxEffort>
    </plugin>
  </gazebo>
  <transmission name="gripper_right_finger_trans">
    <type>transmission_interface/SimpleTransmission</type>
    <joint name="gripper_right_finger_joint">
      <hardwareInterface>hardware_interface/PositionJointInterface</hardwareInterface>
      <hardwareInterface>hardware_interface/JointStateInterface</hardwareInterface>
    </joint>
    <actuator name="gripper_right_motor">
      <mechanicalReduction>1</mechanicalReduction>
      <hardwareInterface>hardware_interface/PositionJointInterface</hardwareInterface>
      <hardwareInterface>hardware_interface/JointStateInterface</hardwareInterface>
    </actuator>
  </transmission>
  <gazebo>
    <gripper name="gripper_right_grasp">
      <grasp_check>
        <attach_steps>3</attach_steps>
        <detach_steps>1</detach_steps>
        <!-- should not change otherwise the object will be attached to the gripper too much time -->
        <min_contact_count>3</min_contact_count>
      </grasp_check>
      <gripper_link>gripper_right_outer_finger_left_link</gripper_link>
      <gripper_link>gripper_right_outer_finger_right_link</gripper_link>
      <palm_link>wrist_right_ft_tool_link</palm_link>
    </gripper>
  </gazebo>
</robot>

